Workbook
Name Equipo_local: League!$D$2:$D$145
Name Equipo_visitante: League!$K$2:$K$145
Name Ganador: League!$BF$2:$BF$145
Name Goles_local: League!$G$2:$G$145
Name Goles_visitante: League!$H$2:$H$145
Name Jornada: League!$A$2:$A$145
Name NombreEquipo: TablaEquipos[Team]

Sheet Home
B2: ADMIN EXCEL CHAMPIONS LEAGUE 2025-2026
J6: Para acceder Click en | K6: 2
B7: =Idiomas!D8 -> Selecciona idioma -> | C7: Español | G7: =Idiomas!D4 -> Introducir resultados Fase de Liga | I7: Item | J7: Español | K7: Inglés
I8: Excel Europa League 2025-2026 | J8: 2 | K8: 2
I9: Excel Conference League 25-26 | J9: 2 | K9: 2
B10: =Idiomas!D18 -> Selecciona Horario -> | C10: España | G10: =Idiomas!D5 -> Introducir resultados Fase KO | I10: Excel Premier League 2025-2026 | J10: 0 | K10: 2
I11: Excel Liga 1ª Division 2025-2026 | J11: 2 | K11: 0
I12: Excel Liga 2ª Division 2025-2026 | J12: 2 | K12: 0
B13: =Idiomas!D13 -> Si en la hoja League, no ves los escudos de los equipos | G13: ADMIN | I13: Excel Liga 1ª Federación (G1 y G2) 2025-2026 | J13: 2 | K13: 0
B14: =Idiomas!D14 -> utiliza el otro archivo que venia en el archivo .zip | I14: Excel Liga F. 2025-2026 | J14: 2 | K14: 0
I15: Excel Libertadores/Sudamericana 2025 | J15: 2 | K15: 0
G16: =Idiomas!D15 -> Clasificación | I16: =Idiomas!D16 -> Excel Mundial 2026 | J16: 2 | K16: 2
I18: =Idiomas!D16 -> Excel Mundial 2026
B22: 25 Participants

Sheet League
A1: =Idiomas!D22 -> Jor. | B1: =Idiomas!D20 -> Fecha | C1: =Idiomas!D21 -> Hora | D1: =Idiomas!D23 -> Equipo Local | E1: Badge | F1: P | G1: =Idiomas!D24 -> Gol | H1: =Idiomas!D25 -> Gol | I1: P | J1: Badge | K1: =Idiomas!D26 -> Equipo Visitante | N1: =Idiomas!D51 -> Pos | O1: Badge | P1: =Idiomas!$D52 -> Equipo | Q1: =Idiomas!$D53 -> Pts | R1: =Idiomas!$D54 -> J | S1: =Idiomas!$D55 -> G | T1: =Idiomas!$D56 -> E | U1: =Idiomas!$D57 -> P | V1: =Idiomas!$D58 -> GF | W1: =Idiomas!$D59 -> GC | X1: =Idiomas!$D60 -> DG | Y1: =CONCATENATE(Q1&" "&Idiomas!$D61) -> Pts C | Z1: =CONCATENATE(R1&" "&Idiomas!$D61) -> J C | AA1: =CONCATENATE(S1&" "&Idiomas!$D61) -> G C | AB1: =CONCATENATE(T1&" "&Idiomas!$D61) -> E C | AC1: =CONCATENATE(U1&" "&Idiomas!$D61) -> P C | AD1: =CONCATENATE(V1&" "&Idiomas!$D61) -> GF C | AE1: =CONCATENATE(W1&" "&Idiomas!$D61) -> GC C | AF1: =CONCATENATE(X1&" "&Idiomas!$D61) -> DG C | AG1: =CONCATENATE(Q1&" "&Idiomas!$D62) -> Pts F | AH1: =CONCATENATE(R1&" "&Idiomas!$D62) -> J F | AI1: =CONCATENATE(S1&" "&Idiomas!$D62) -> G F | AJ1: =CONCATENATE(T1&" "&Idiomas!$D62) -> E F | AK1: =CONCATENATE(U1&" "&Idiomas!$D62) -> P F | AL1: =CONCATENATE(V1&" "&Idiomas!$D62) -> GF F | AM1: =CONCATENATE(W1&" "&Idiomas!$D62) -> GC F | AN1: =CONCATENATE(X1&" "&Idiomas!$D62) -> DG F | AO1: P-O | AP1: DF-O | AQ1: GF_O | AS1: =Idiomas!D64 -> Seleccionar el orden de los empatados. | AV1: =COUNTIF($AV$2:$AV$37,">"&1) -> 0 | AZ1: =P1 -> Equipo | BA1: =Idiomas!D63 -> Puntos penalizados | BF1: Winner | BI1: {=TRANSPOSE(Calcs!$A$2:$A$37)} -> Ajax | BJ1: Arsenal | BK1: Atalanta | BL1: Athletic Bilbao | BM1: Atlético Madrid | BN1: Barcelona | BO1: Bayer Leverkusen | BP1: Bayern München | BQ1: Benfica | BR1: Bodø/Glimt | BS1: Borussia Dortmund | BT1: Brugge | BU1: Chelsea | BV1: Copenhagen | BW1: Eintracht Frankfurt | BX1: Galatasaray | BY1: Inter Milan | BZ1: Juventus | CA1: Kairat Almaty | CB1: Liverpool | CC1: Manchester City | CD1: Marseille | CE1: Monaco | CF1: Napoli | CG1: Newcastle | CH1: Olympiakos | CI1: Pafos | CJ1: PSG | CK1: PSV Eindhoven | CL1: Qarabağ | CM1: Real Madrid | CN1: Slavia Praha | CO1: Sporting Portugal | CP1: Tottenham | CQ1: Union Saint-Gilloise | CR1: Villarreal
A2: 1 | B2: =Horarios!C2 -> 45916.781 | C2: =Horarios!C2 -> 45916.781 | D2: Athletic Bilbao | E2: =INDEX(TablaEquipos[Badge],MATCH(D2,TablaEquipos[Team],0)) -> #VALUE! | G2: 0 | H2: 2 | J2: =INDEX(TablaEquipos[Badge],MATCH(K2,TablaEquipos[Team],0)) -> #VALUE! | K2: Arsenal | N2: 1 | O2: =INDEX(TablaEquipos[],MATCH(P2,TablaEquipos[Team],0),MATCH($O$1,TablaEquipos[#Headers],0)) -> #VALUE! | P2: =IFERROR(INDEX(Calcs!A$2:A$37,MATCH($N2,Calcs!$CJ$2:$CJ$37,0)),"") -> Arsenal | Q2: =IFERROR(INDEX(Calcs!$B$2:$AB$37,MATCH($N2,Calcs!$CJ$2:$CJ$37,0),MATCH(Q$1,Calcs!$B$1:$AB$1,0)),"") -> 21 | R2: =IFERROR(INDEX(Calcs!$B$2:$AB$37,MATCH($N2,Calcs!$CJ$2:$CJ$37,0),MATCH(R$1,Calcs!$B$1:$AB$1,0)),"") -> 7 | S2: =IFERROR(INDEX(Calcs!$B$2:$AB$37,MATCH($N2,Calcs!$CJ$2:$CJ$37,0),MATCH(S$1,Calcs!$B$1:$AB$1,0)),"") -> 7 | T2: =IFERROR(INDEX(Calcs!$B$2:$AB$37,MATCH($N2,Calcs!$CJ$2:$CJ$37,0),MATCH(T$1,Calcs!$B$1:$AB$1,0)),"") -> 0 | U2: =IFERROR(INDEX(Calcs!$B$2:$AB$37,MATCH($N2,Calcs!$CJ$2:$CJ$37,0),MATCH(U$1,Calcs!$B$1:$AB$1,0)),"") -> 0 | V2: =IFERROR(INDEX(Calcs!$B$2:$AB$37,MATCH($N2,Calcs!$CJ$2:$CJ$37,0),MATCH(V$1,Calcs!$B$1:$AB$1,0)),"") -> 20 | W2: =IFERROR(INDEX(Calcs!$B$2:$AB$37,MATCH($N2,Calcs!$CJ$2:$CJ$37,0),MATCH(W$1,Calcs!$B$1:$AB$1,0)),"") -> 2 | X2: =IFERROR(INDEX(Calcs!$B$2:$AB$37,MATCH($N2,Calcs!$CJ$2:$CJ$37,0),MATCH(X$1,Calcs!$B$1:$AB$1,0)),"") -> 18 | ... AQ2: =IFERROR(INDEX(Calcs!$B$2:$AB$37,MATCH($N2,Calcs!$CJ$2:$CJ$37,0),MATCH(AQ$1,Calcs!$B$1:$AB$1,0)),"") -> 85 | AS2: =INDEX(Calcs!A$2:A$37,MATCH($N2,Calcs!$CF$2:$CF$37,0)) -> Arsenal | AU2: =INDEX(Calcs!$BZ$2:$BZ$37,MATCH($AS2,Calcs!$A$2:$A$37,0)) -> 1 | AV2: =COUNTIF($AU$2:$AU$37,$AU2) -> 1 | AW2: =AU2&"."&AV2 -> 1.1 | AX2: {=OFFSET($N$2,AU2-1,0,AV2,1)} -> 1 | AZ2: =TablaEquipos[[#This Row],[Team]] -> Ajax | BF2: =IF(OR(G2="",H2=""),"Pendiente",IF(G2>H2,"Local",IF(G2<H2,"Visitante","Empate"))) -> Visitante | BG2: {=IFERROR(INDEX(Equipo_local,SMALL(IF(BI$1=Equipo_visitante,ROW(Equipo_local)-MIN(ROW(Equipo_visitante))+1,""),ROW()-1)),"")} -> Marseille | BH2: 1 | BI2: {=IFERROR(INDEX(Equipo_visitante,MATCH($BH2&BI$1,Jornada&Equipo_local,0)),INDEX(Equipo_local,MATCH($BH2&BI$1,Jornada&Equipo_visitante,0)))} -> Inter Milan | BJ2: {=IFERROR(INDEX(Equipo_visitante,MATCH($BH2&BJ$1,Jornada&Equipo_local,0)),INDEX(Equipo_local,MATCH($BH2&BJ$1,Jornada&Equipo_visitante,0)))} -> Athletic Bilbao | BK2: {=IFERROR(INDEX(Equipo_visitante,MATCH($BH2&BK$1,Jornada&Equipo_local,0)),INDEX(Equipo_local,MATCH($BH2&BK$1,Jornada&Equipo_visitante,0)))} -> PSG | BL2: {=IFERROR(INDEX(Equipo_visitante,MATCH($BH2&BL$1,Jornada&Equipo_local,0)),INDEX(Equipo_local,MATCH($BH2&BL$1,Jornada&Equipo_visitante,0)))} -> Arsenal | BM2: {=IFERROR(INDEX(Equipo_visitante,MATCH($BH2&BM$1,Jornada&Equipo_local,0)),INDEX(Equipo_local,MATCH($BH2&BM$1,Jornada&Equipo_visitante,0)))} -> Liverpool | BN2: {=IFERROR(INDEX(Equipo_visitante,MATCH($BH2&BN$1,Jornada&Equipo_local,0)),INDEX(Equipo_local,MATCH($BH2&BN$1,Jornada&Equipo_visitante,0)))} -> Newcastle | BO2: {=IFERROR(INDEX(Equipo_visitante,MATCH($BH2&BO$1,Jornada&Equipo_local,0)),INDEX(Equipo_local,MATCH($BH2&BO$1,Jornada&Equipo_visitante,0)))} -> Copenhagen | BP2: {=IFERROR(INDEX(Equipo_visitante,MATCH($BH2&BP$1,Jornada&Equipo_local,0)),INDEX(Equipo_local,MATCH($BH2&BP$1,Jornada&Equipo_visitante,0)))} -> Chelsea | ... CR2: {=IFERROR(INDEX(Equipo_visitante,MATCH($BH2&CR$1,Jornada&Equipo_local,0)),INDEX(Equipo_local,MATCH($BH2&CR$1,Jornada&Equipo_visitante,0)))} -> Tottenham
A3: 1 | B3: =Horarios!C3 -> 45916.781 | C3: =Horarios!C3 -> 45916.781 | D3: PSV Eindhoven | E3: =INDEX(TablaEquipos[Badge],MATCH(D3,TablaEquipos[Team],0)) -> #VALUE! | G3: 1 | H3: 3 | J3: =INDEX(TablaEquipos[Badge],MATCH(K3,TablaEquipos[Team],0)) -> #VALUE! | K3: Union Saint-Gilloise | N3: 2 | O3: =INDEX(TablaEquipos[],MATCH(P3,TablaEquipos[Team],0),MATCH($O$1,TablaEquipos[#Headers],0)) -> #VALUE! | P3: =IFERROR(INDEX(Calcs!A$2:A$37,MATCH($N3,Calcs!$CJ$2:$CJ$37,0)),"") -> Bayern München | Q3: =IFERROR(INDEX(Calcs!$B$2:$AB$37,MATCH($N3,Calcs!$CJ$2:$CJ$37,0),MATCH(Q$1,Calcs!$B$1:$AB$1,0)),"") -> 18 | R3: =IFERROR(INDEX(Calcs!$B$2:$AB$37,MATCH($N3,Calcs!$CJ$2:$CJ$37,0),MATCH(R$1,Calcs!$B$1:$AB$1,0)),"") -> 7 | S3: =IFERROR(INDEX(Calcs!$B$2:$AB$37,MATCH($N3,Calcs!$CJ$2:$CJ$37,0),MATCH(S$1,Calcs!$B$1:$AB$1,0)),"") -> 6 | T3: =IFERROR(INDEX(Calcs!$B$2:$AB$37,MATCH($N3,Calcs!$CJ$2:$CJ$37,0),MATCH(T$1,Calcs!$B$1:$AB$1,0)),"") -> 0 | U3: =IFERROR(INDEX(Calcs!$B$2:$AB$37,MATCH($N3,Calcs!$CJ$2:$CJ$37,0),MATCH(U$1,Calcs!$B$1:$AB$1,0)),"") -> 1 | V3: =IFERROR(INDEX(Calcs!$B$2:$AB$37,MATCH($N3,Calcs!$CJ$2:$CJ$37,0),MATCH(V$1,Calcs!$B$1:$AB$1,0)),"") -> 20 | W3: =IFERROR(INDEX(Calcs!$B$2:$AB$37,MATCH($N3,Calcs!$CJ$2:$CJ$37,0),MATCH(W$1,Calcs!$B$1:$AB$1,0)),"") -> 7 | X3: =IFERROR(INDEX(Calcs!$B$2:$AB$37,MATCH($N3,Calcs!$CJ$2:$CJ$37,0),MATCH(X$1,Calcs!$B$1:$AB$1,0)),"") -> 13 | ... AQ3: =IFERROR(INDEX(Calcs!$B$2:$AB$37,MATCH($N3,Calcs!$CJ$2:$CJ$37,0),MATCH(AQ$1,Calcs!$B$1:$AB$1,0)),"") -> 106 | AS3: =INDEX(Calcs!A$2:A$37,MATCH($N3,Calcs!$CF$2:$CF$37,0)) -> Bayern München | AU3: =INDEX(Calcs!$BZ$2:$BZ$37,MATCH($AS3,Calcs!$A$2:$A$37,0)) -> 2 | AV3: =COUNTIF($AU$2:$AU$37,$AU3) -> 1 | AW3: =AU3&"."&AV3 -> 2.1 | AZ3: =TablaEquipos[[#This Row],[Team]] -> Arsenal | BF3: =IF(OR(G3="",H3=""),"Pendiente",IF(G3>H3,"Local",IF(G3<H3,"Visitante","Empate"))) -> Visitante | BH3: 2 | BI3: {=IFERROR(INDEX(Equipo_visitante,MATCH($BH3&BI$1,Jornada&Equipo_local,0)),INDEX(Equipo_local,MATCH($BH3&BI$1,Jornada&Equipo_visitante,0)))} -> Marseille | BJ3: {=IFERROR(INDEX(Equipo_visitante,MATCH($BH3&BJ$1,Jornada&Equipo_local,0)),INDEX(Equipo_local,MATCH($BH3&BJ$1,Jornada&Equipo_visitante,0)))} -> Olympiakos | BK3: {=IFERROR(INDEX(Equipo_visitante,MATCH($BH3&BK$1,Jornada&Equipo_local,0)),INDEX(Equipo_local,MATCH($BH3&BK$1,Jornada&Equipo_visitante,0)))} -> Brugge | BL3: {=IFERROR(INDEX(Equipo_visitante,MATCH($BH3&BL$1,Jornada&Equipo_local,0)),INDEX(Equipo_local,MATCH($BH3&BL$1,Jornada&Equipo_visitante,0)))} -> Borussia Dortmund | BM3: {=IFERROR(INDEX(Equipo_visitante,MATCH($BH3&BM$1,Jornada&Equipo_local,0)),INDEX(Equipo_local,MATCH($BH3&BM$1,Jornada&Equipo_visitante,0)))} -> Eintracht Frankfurt | BN3: {=IFERROR(INDEX(Equipo_visitante,MATCH($BH3&BN$1,Jornada&Equipo_local,0)),INDEX(Equipo_local,MATCH($BH3&BN$1,Jornada&Equipo_visitante,0)))} -> PSG | BO3: {=IFERROR(INDEX(Equipo_visitante,MATCH($BH3&BO$1,Jornada&Equipo_local,0)),INDEX(Equipo_local,MATCH($BH3&BO$1,Jornada&Equipo_visitante,0)))} -> PSV Eindhoven | BP3: {=IFERROR(INDEX(Equipo_visitante,MATCH($BH3&BP$1,Jornada&Equipo_local,0)),INDEX(Equipo_local,MATCH($BH3&BP$1,Jornada&Equipo_visitante,0)))} -> Pafos | ... CR3: {=IFERROR(INDEX(Equipo_visitante,MATCH($BH3&CR$1,Jornada&Equipo_local,0)),INDEX(Equipo_local,MATCH($BH3&CR$1,Jornada&Equipo_visitante,0)))} -> Juventus
A4: 1 | B4: =Horarios!C4 -> 45916.875 | C4: =Horarios!C4 -> 45916.875 | D4: Juventus | E4: =INDEX(TablaEquipos[Badge],MATCH(D4,TablaEquipos[Team],0)) -> #VALUE! | G4: 4 | H4: 4 | J4: =INDEX(TablaEquipos[Badge],MATCH(K4,TablaEquipos[Team],0)) -> #VALUE! | K4: Borussia Dortmund | N4: 3 | O4: =INDEX(TablaEquipos[],MATCH(P4,TablaEquipos[Team],0),MATCH($O$1,TablaEquipos[#Headers],0)) -> #VALUE! | P4: =IFERROR(INDEX(Calcs!A$2:A$37,MATCH($N4,Calcs!$CJ$2:$CJ$37,0)),"") -> Real Madrid | Q4: =IFERROR(INDEX(Calcs!$B$2:$AB$37,MATCH($N4,Calcs!$CJ$2:$CJ$37,0),MATCH(Q$1,Calcs!$B$1:$AB$1,0)),"") -> 15 | R4: =IFERROR(INDEX(Calcs!$B$2:$AB$37,MATCH($N4,Calcs!$CJ$2:$CJ$37,0),MATCH(R$1,Calcs!$B$1:$AB$1,0)),"") -> 7 | S4: =IFERROR(INDEX(Calcs!$B$2:$AB$37,MATCH($N4,Calcs!$CJ$2:$CJ$37,0),MATCH(S$1,Calcs!$B$1:$AB$1,0)),"") -> 5 | T4: =IFERROR(INDEX(Calcs!$B$2:$AB$37,MATCH($N4,Calcs!$CJ$2:$CJ$37,0),MATCH(T$1,Calcs!$B$1:$AB$1,0)),"") -> 0 | U4: =IFERROR(INDEX(Calcs!$B$2:$AB$37,MATCH($N4,Calcs!$CJ$2:$CJ$37,0),MATCH(U$1,Calcs!$B$1:$AB$1,0)),"") -> 2 | V4: =IFERROR(INDEX(Calcs!$B$2:$AB$37,MATCH($N4,Calcs!$CJ$2:$CJ$37,0),MATCH(V$1,Calcs!$B$1:$AB$1,0)),"") -> 19 | W4: =IFERROR(INDEX(Calcs!$B$2:$AB$37,MATCH($N4,Calcs!$CJ$2:$CJ$37,0),MATCH(W$1,Calcs!$B$1:$AB$1,0)),"") -> 8 | X4: =IFERROR(INDEX(Calcs!$B$2:$AB$37,MATCH($N4,Calcs!$CJ$2:$CJ$37,0),MATCH(X$1,Calcs!$B$1:$AB$1,0)),"") -> 11 | ... AQ4: =IFERROR(INDEX(Calcs!$B$2:$AB$37,MATCH($N4,Calcs!$CJ$2:$CJ$37,0),MATCH(AQ$1,Calcs!$B$1:$AB$1,0)),"") -> 79 | AS4: =INDEX(Calcs!A$2:A$37,MATCH($N4,Calcs!$CF$2:$CF$37,0)) -> Real Madrid | AU4: =INDEX(Calcs!$BZ$2:$BZ$37,MATCH($AS4,Calcs!$A$2:$A$37,0)) -> 3 | AV4: =COUNTIF($AU$2:$AU$37,$AU4) -> 1 | AW4: =AU4&"."&AV4 -> 3.1 | AZ4: =TablaEquipos[[#This Row],[Team]] -> Atalanta | BF4: =IF(OR(G4="",H4=""),"Pendiente",IF(G4>H4,"Local",IF(G4<H4,"Visitante","Empate"))) -> Empate | BH4: 3 | BI4: {=IFERROR(INDEX(Equipo_visitante,MATCH($BH4&BI$1,Jornada&Equipo_local,0)),INDEX(Equipo_local,MATCH($BH4&BI$1,Jornada&Equipo_visitante,0)))} -> Chelsea | BJ4: {=IFERROR(INDEX(Equipo_visitante,MATCH($BH4&BJ$1,Jornada&Equipo_local,0)),INDEX(Equipo_local,MATCH($BH4&BJ$1,Jornada&Equipo_visitante,0)))} -> Atlético Madrid | BK4: {=IFERROR(INDEX(Equipo_visitante,MATCH($BH4&BK$1,Jornada&Equipo_local,0)),INDEX(Equipo_local,MATCH($BH4&BK$1,Jornada&Equipo_visitante,0)))} -> Slavia Praha | BL4: {=IFERROR(INDEX(Equipo_visitante,MATCH($BH4&BL$1,Jornada&Equipo_local,0)),INDEX(Equipo_local,MATCH($BH4&BL$1,Jornada&Equipo_visitante,0)))} -> Qarabağ | BM4: {=IFERROR(INDEX(Equipo_visitante,MATCH($BH4&BM$1,Jornada&Equipo_local,0)),INDEX(Equipo_local,MATCH($BH4&BM$1,Jornada&Equipo_visitante,0)))} -> Arsenal | BN4: {=IFERROR(INDEX(Equipo_visitante,MATCH($BH4&BN$1,Jornada&Equipo_local,0)),INDEX(Equipo_local,MATCH($BH4&BN$1,Jornada&Equipo_visitante,0)))} -> Olympiakos | BO4: {=IFERROR(INDEX(Equipo_visitante,MATCH($BH4&BO$1,Jornada&Equipo_local,0)),INDEX(Equipo_local,MATCH($BH4&BO$1,Jornada&Equipo_visitante,0)))} -> PSG | BP4: {=IFERROR(INDEX(Equipo_visitante,MATCH($BH4&BP$1,Jornada&Equipo_local,0)),INDEX(Equipo_local,MATCH($BH4&BP$1,Jornada&Equipo_visitante,0)))} -> Brugge | ... CR4: {=IFERROR(INDEX(Equipo_visitante,MATCH($BH4&CR$1,Jornada&Equipo_local,0)),INDEX(Equipo_local,MATCH($BH4&CR$1,Jornada&Equipo_visitante,0)))} -> Manchester City
A5: 1 | B5: =Horarios!C5 -> 45916.875 | C5: =Horarios!C5 -> 45916.875 | D5: Real Madrid | E5: =INDEX(TablaEquipos[Badge],MATCH(D5,TablaEquipos[Team],0)) -> #VALUE! | G5: 2 | H5: 1 | J5: =INDEX(TablaEquipos[Badge],MATCH(K5,TablaEquipos[Team],0)) -> #VALUE! | K5: Marseille | N5: 4 | O5: =INDEX(TablaEquipos[],MATCH(P5,TablaEquipos[Team],0),MATCH($O$1,TablaEquipos[#Headers],0)) -> #VALUE! | P5: =IFERROR(INDEX(Calcs!A$2:A$37,MATCH($N5,Calcs!$CJ$2:$CJ$37,0)),"") -> Liverpool | Q5: =IFERROR(INDEX(Calcs!$B$2:$AB$37,MATCH($N5,Calcs!$CJ$2:$CJ$37,0),MATCH(Q$1,Calcs!$B$1:$AB$1,0)),"") -> 15 | R5: =IFERROR(INDEX(Calcs!$B$2:$AB$37,MATCH($N5,Calcs!$CJ$2:$CJ$37,0),MATCH(R$1,Calcs!$B$1:$AB$1,0)),"") -> 7 | S5: =IFERROR(INDEX(Calcs!$B$2:$AB$37,MATCH($N5,Calcs!$CJ$2:$CJ$37,0),MATCH(S$1,Calcs!$B$1:$AB$1,0)),"") -> 5 | T5: =IFERROR(INDEX(Calcs!$B$2:$AB$37,MATCH($N5,Calcs!$CJ$2:$CJ$37,0),MATCH(T$1,Calcs!$B$1:$AB$1,0)),"") -> 0 | U5: =IFERROR(INDEX(Calcs!$B$2:$AB$37,MATCH($N5,Calcs!$CJ$2:$CJ$37,0),MATCH(U$1,Calcs!$B$1:$AB$1,0)),"") -> 2 | V5: =IFERROR(INDEX(Calcs!$B$2:$AB$37,MATCH($N5,Calcs!$CJ$2:$CJ$37,0),MATCH(V$1,Calcs!$B$1:$AB$1,0)),"") -> 14 | W5: =IFERROR(INDEX(Calcs!$B$2:$AB$37,MATCH($N5,Calcs!$CJ$2:$CJ$37,0),MATCH(W$1,Calcs!$B$1:$AB$1,0)),"") -> 8 | X5: =IFERROR(INDEX(Calcs!$B$2:$AB$37,MATCH($N5,Calcs!$CJ$2:$CJ$37,0),MATCH(X$1,Calcs!$B$1:$AB$1,0)),"") -> 6 | ... AQ5: =IFERROR(INDEX(Calcs!$B$2:$AB$37,MATCH($N5,Calcs!$CJ$2:$CJ$37,0),MATCH(AQ$1,Calcs!$B$1:$AB$1,0)),"") -> 106 | AS5: =INDEX(Calcs!A$2:A$37,MATCH($N5,Calcs!$CF$2:$CF$37,0)) -> Liverpool | AU5: =INDEX(Calcs!$BZ$2:$BZ$37,MATCH($AS5,Calcs!$A$2:$A$37,0)) -> 4 | AV5: =COUNTIF($AU$2:$AU$37,$AU5) -> 1 | AW5: =AU5&"."&AV5 -> 4.1 | AZ5: =TablaEquipos[[#This Row],[Team]] -> Athletic Bilbao | BF5: =IF(OR(G5="",H5=""),"Pendiente",IF(G5>H5,"Local",IF(G5<H5,"Visitante","Empate"))) -> Local | BH5: 4 | BI5: {=IFERROR(INDEX(Equipo_visitante,MATCH($BH5&BI$1,Jornada&Equipo_local,0)),INDEX(Equipo_local,MATCH($BH5&BI$1,Jornada&Equipo_visitante,0)))} -> Galatasaray | BJ5: {=IFERROR(INDEX(Equipo_visitante,MATCH($BH5&BJ$1,Jornada&Equipo_local,0)),INDEX(Equipo_local,MATCH($BH5&BJ$1,Jornada&Equipo_visitante,0)))} -> Slavia Praha | BK5: {=IFERROR(INDEX(Equipo_visitante,MATCH($BH5&BK$1,Jornada&Equipo_local,0)),INDEX(Equipo_local,MATCH($BH5&BK$1,Jornada&Equipo_visitante,0)))} -> Marseille | BL5: {=IFERROR(INDEX(Equipo_visitante,MATCH($BH5&BL$1,Jornada&Equipo_local,0)),INDEX(Equipo_local,MATCH($BH5&BL$1,Jornada&Equipo_visitante,0)))} -> Newcastle | BM5: {=IFERROR(INDEX(Equipo_visitante,MATCH($BH5&BM$1,Jornada&Equipo_local,0)),INDEX(Equipo_local,MATCH($BH5&BM$1,Jornada&Equipo_visitante,0)))} -> Union Saint-Gilloise | BN5: {=IFERROR(INDEX(Equipo_visitante,MATCH($BH5&BN$1,Jornada&Equipo_local,0)),INDEX(Equipo_local,MATCH($BH5&BN$1,Jornada&Equipo_visitante,0)))} -> Brugge | BO5: {=IFERROR(INDEX(Equipo_visitante,MATCH($BH5&BO$1,Jornada&Equipo_local,0)),INDEX(Equipo_local,MATCH($BH5&BO$1,Jornada&Equipo_visitante,0)))} -> Benfica | BP5: {=IFERROR(INDEX(Equipo_visitante,MATCH($BH5&BP$1,Jornada&Equipo_local,0)),INDEX(Equipo_local,MATCH($BH5&BP$1,Jornada&Equipo_visitante,0)))} -> PSG | ... CR5: {=IFERROR(INDEX(Equipo_visitante,MATCH($BH5&CR$1,Jornada&Equipo_local,0)),INDEX(Equipo_local,MATCH($BH5&CR$1,Jornada&Equipo_visitante,0)))} -> Pafos
A6: 1 | B6: =Horarios!C6 -> 45916.875 | C6: =Horarios!C6 -> 45916.875 | D6: Benfica | E6: =INDEX(TablaEquipos[Badge],MATCH(D6,TablaEquipos[Team],0)) -> #VALUE! | G6: 2 | H6: 3 | J6: =INDEX(TablaEquipos[Badge],MATCH(K6,TablaEquipos[Team],0)) -> #VALUE! | K6: Qarabağ | N6: 5 | O6: =INDEX(TablaEquipos[],MATCH(P6,TablaEquipos[Team],0),MATCH($O$1,TablaEquipos[#Headers],0)) -> #VALUE! | P6: =IFERROR(INDEX(Calcs!A$2:A$37,MATCH($N6,Calcs!$CJ$2:$CJ$37,0)),"") -> Tottenham | Q6: =IFERROR(INDEX(Calcs!$B$2:$AB$37,MATCH($N6,Calcs!$CJ$2:$CJ$37,0),MATCH(Q$1,Calcs!$B$1:$AB$1,0)),"") -> 14 | R6: =IFERROR(INDEX(Calcs!$B$2:$AB$37,MATCH($N6,Calcs!$CJ$2:$CJ$37,0),MATCH(R$1,Calcs!$B$1:$AB$1,0)),"") -> 7 | S6: =IFERROR(INDEX(Calcs!$B$2:$AB$37,MATCH($N6,Calcs!$CJ$2:$CJ$37,0),MATCH(S$1,Calcs!$B$1:$AB$1,0)),"") -> 4 | T6: =IFERROR(INDEX(Calcs!$B$2:$AB$37,MATCH($N6,Calcs!$CJ$2:$CJ$37,0),MATCH(T$1,Calcs!$B$1:$AB$1,0)),"") -> 2 | U6: =IFERROR(INDEX(Calcs!$B$2:$AB$37,MATCH($N6,Calcs!$CJ$2:$CJ$37,0),MATCH(U$1,Calcs!$B$1:$AB$1,0)),"") -> 1 | V6: =IFERROR(INDEX(Calcs!$B$2:$AB$37,MATCH($N6,Calcs!$CJ$2:$CJ$37,0),MATCH(V$1,Calcs!$B$1:$AB$1,0)),"") -> 15 | W6: =IFERROR(INDEX(Calcs!$B$2:$AB$37,MATCH($N6,Calcs!$CJ$2:$CJ$37,0),MATCH(W$1,Calcs!$B$1:$AB$1,0)),"") -> 7 | X6: =IFERROR(INDEX(Calcs!$B$2:$AB$37,MATCH($N6,Calcs!$CJ$2:$CJ$37,0),MATCH(X$1,Calcs!$B$1:$AB$1,0)),"") -> 8 | ... AQ6: =IFERROR(INDEX(Calcs!$B$2:$AB$37,MATCH($N6,Calcs!$CJ$2:$CJ$37,0),MATCH(AQ$1,Calcs!$B$1:$AB$1,0)),"") -> 89 | AS6: =INDEX(Calcs!A$2:A$37,MATCH($N6,Calcs!$CF$2:$CF$37,0)) -> Tottenham | AU6: =INDEX(Calcs!$BZ$2:$BZ$37,MATCH($AS6,Calcs!$A$2:$A$37,0)) -> 5 | AV6: =COUNTIF($AU$2:$AU$37,$AU6) -> 1 | AW6: =AU6&"."&AV6 -> 5.1 | AZ6: =TablaEquipos[[#This Row],[Team]] -> Atlético Madrid | BF6: =IF(OR(G6="",H6=""),"Pendiente",IF(G6>H6,"Local",IF(G6<H6,"Visitante","Empate"))) -> Visitante | BG6: {=IFERROR(INDEX(Equipo_visitante,SMALL(IF(BI$1=Equipo_local,ROW(Equipo_visitante)-MIN(ROW(Equipo_local))+1,""),ROW()-5)),"")} -> Inter Milan | BH6: 5 | BI6: {=IFERROR(INDEX(Equipo_visitante,MATCH($BH6&BI$1,Jornada&Equipo_local,0)),INDEX(Equipo_local,MATCH($BH6&BI$1,Jornada&Equipo_visitante,0)))} -> Benfica | BJ6: {=IFERROR(INDEX(Equipo_visitante,MATCH($BH6&BJ$1,Jornada&Equipo_local,0)),INDEX(Equipo_local,MATCH($BH6&BJ$1,Jornada&Equipo_visitante,0)))} -> Bayern München | BK6: {=IFERROR(INDEX(Equipo_visitante,MATCH($BH6&BK$1,Jornada&Equipo_local,0)),INDEX(Equipo_local,MATCH($BH6&BK$1,Jornada&Equipo_visitante,0)))} -> Eintracht Frankfurt | BL6: {=IFERROR(INDEX(Equipo_visitante,MATCH($BH6&BL$1,Jornada&Equipo_local,0)),INDEX(Equipo_local,MATCH($BH6&BL$1,Jornada&Equipo_visitante,0)))} -> Slavia Praha | BM6: {=IFERROR(INDEX(Equipo_visitante,MATCH($BH6&BM$1,Jornada&Equipo_local,0)),INDEX(Equipo_local,MATCH($BH6&BM$1,Jornada&Equipo_visitante,0)))} -> Inter Milan | BN6: {=IFERROR(INDEX(Equipo_visitante,MATCH($BH6&BN$1,Jornada&Equipo_local,0)),INDEX(Equipo_local,MATCH($BH6&BN$1,Jornada&Equipo_visitante,0)))} -> Chelsea | BO6: {=IFERROR(INDEX(Equipo_visitante,MATCH($BH6&BO$1,Jornada&Equipo_local,0)),INDEX(Equipo_local,MATCH($BH6&BO$1,Jornada&Equipo_visitante,0)))} -> Manchester City | BP6: {=IFERROR(INDEX(Equipo_visitante,MATCH($BH6&BP$1,Jornada&Equipo_local,0)),INDEX(Equipo_local,MATCH($BH6&BP$1,Jornada&Equipo_visitante,0)))} -> Arsenal | ... CR6: {=IFERROR(INDEX(Equipo_visitante,MATCH($BH6&CR$1,Jornada&Equipo_local,0)),INDEX(Equipo_local,MATCH($BH6&CR$1,Jornada&Equipo_visitante,0)))} -> Borussia Dortmund
A7: 1 | B7: =Horarios!C7 -> 45916.875 | C7: =Horarios!C7 -> 45916.875 | D7: Tottenham | E7: =INDEX(TablaEquipos[Badge],MATCH(D7,TablaEquipos[Team],0)) -> #VALUE! | G7: 1 | H7: 0 | J7: =INDEX(TablaEquipos[Badge],MATCH(K7,TablaEquipos[Team],0)) -> #VALUE! | K7: Villarreal | N7: 6 | O7: =INDEX(TablaEquipos[],MATCH(P7,TablaEquipos[Team],0),MATCH($O$1,TablaEquipos[#Headers],0)) -> #VALUE! | P7: =IFERROR(INDEX(Calcs!A$2:A$37,MATCH($N7,Calcs!$CJ$2:$CJ$37,0)),"") -> PSG | Q7: =IFERROR(INDEX(Calcs!$B$2:$AB$37,MATCH($N7,Calcs!$CJ$2:$CJ$37,0),MATCH(Q$1,Calcs!$B$1:$AB$1,0)),"") -> 13 | R7: =IFERROR(INDEX(Calcs!$B$2:$AB$37,MATCH($N7,Calcs!$CJ$2:$CJ$37,0),MATCH(R$1,Calcs!$B$1:$AB$1,0)),"") -> 7 | S7: =IFERROR(INDEX(Calcs!$B$2:$AB$37,MATCH($N7,Calcs!$CJ$2:$CJ$37,0),MATCH(S$1,Calcs!$B$1:$AB$1,0)),"") -> 4 | T7: =IFERROR(INDEX(Calcs!$B$2:$AB$37,MATCH($N7,Calcs!$CJ$2:$CJ$37,0),MATCH(T$1,Calcs!$B$1:$AB$1,0)),"") -> 1 | U7: =IFERROR(INDEX(Calcs!$B$2:$AB$37,MATCH($N7,Calcs!$CJ$2:$CJ$37,0),MATCH(U$1,Calcs!$B$1:$AB$1,0)),"") -> 2 | V7: =IFERROR(INDEX(Calcs!$B$2:$AB$37,MATCH($N7,Calcs!$CJ$2:$CJ$37,0),MATCH(V$1,Calcs!$B$1:$AB$1,0)),"") -> 20 | W7: =IFERROR(INDEX(Calcs!$B$2:$AB$37,MATCH($N7,Calcs!$CJ$2:$CJ$37,0),MATCH(W$1,Calcs!$B$1:$AB$1,0)),"") -> 10 | X7: =IFERROR(INDEX(Calcs!$B$2:$AB$37,MATCH($N7,Calcs!$CJ$2:$CJ$37,0),MATCH(X$1,Calcs!$B$1:$AB$1,0)),"") -> 10 | ... AQ7: =IFERROR(INDEX(Calcs!$B$2:$AB$37,MATCH($N7,Calcs!$CJ$2:$CJ$37,0),MATCH(AQ$1,Calcs!$B$1:$AB$1,0)),"") -> 110 | AS7: =INDEX(Calcs!A$2:A$37,MATCH($N7,Calcs!$CF$2:$CF$37,0)) -> PSG | AU7: =INDEX(Calcs!$BZ$2:$BZ$37,MATCH($AS7,Calcs!$A$2:$A$37,0)) -> 6 | AV7: =COUNTIF($AU$2:$AU$37,$AU7) -> 1 | AW7: =AU7&"."&AV7 -> 6.1 | AZ7: =TablaEquipos[[#This Row],[Team]] -> Barcelona | BF7: =IF(OR(G7="",H7=""),"Pendiente",IF(G7>H7,"Local",IF(G7<H7,"Visitante","Empate"))) -> Local | BH7: 6 | BI7: {=IFERROR(INDEX(Equipo_visitante,MATCH($BH7&BI$1,Jornada&Equipo_local,0)),INDEX(Equipo_local,MATCH($BH7&BI$1,Jornada&Equipo_visitante,0)))} -> Qarabağ | BJ7: {=IFERROR(INDEX(Equipo_visitante,MATCH($BH7&BJ$1,Jornada&Equipo_local,0)),INDEX(Equipo_local,MATCH($BH7&BJ$1,Jornada&Equipo_visitante,0)))} -> Brugge | BK7: {=IFERROR(INDEX(Equipo_visitante,MATCH($BH7&BK$1,Jornada&Equipo_local,0)),INDEX(Equipo_local,MATCH($BH7&BK$1,Jornada&Equipo_visitante,0)))} -> Chelsea | BL7: {=IFERROR(INDEX(Equipo_visitante,MATCH($BH7&BL$1,Jornada&Equipo_local,0)),INDEX(Equipo_local,MATCH($BH7&BL$1,Jornada&Equipo_visitante,0)))} -> PSG | BM7: {=IFERROR(INDEX(Equipo_visitante,MATCH($BH7&BM$1,Jornada&Equipo_local,0)),INDEX(Equipo_local,MATCH($BH7&BM$1,Jornada&Equipo_visitante,0)))} -> PSV Eindhoven | BN7: {=IFERROR(INDEX(Equipo_visitante,MATCH($BH7&BN$1,Jornada&Equipo_local,0)),INDEX(Equipo_local,MATCH($BH7&BN$1,Jornada&Equipo_visitante,0)))} -> Eintracht Frankfurt | BO7: {=IFERROR(INDEX(Equipo_visitante,MATCH($BH7&BO$1,Jornada&Equipo_local,0)),INDEX(Equipo_local,MATCH($BH7&BO$1,Jornada&Equipo_visitante,0)))} -> Newcastle | BP7: {=IFERROR(INDEX(Equipo_visitante,MATCH($BH7&BP$1,Jornada&Equipo_local,0)),INDEX(Equipo_local,MATCH($BH7&BP$1,Jornada&Equipo_visitante,0)))} -> Sporting Portugal | ... CR7: {=IFERROR(INDEX(Equipo_visitante,MATCH($BH7&CR$1,Jornada&Equipo_local,0)),INDEX(Equipo_local,MATCH($BH7&CR$1,Jornada&Equipo_visitante,0)))} -> Copenhagen
A8: 1 | B8: =Horarios!C8 -> 45917.781 | C8: =Horarios!C8 -> 45917.781 | D8: Olympiakos | E8: =INDEX(TablaEquipos[Badge],MATCH(D8,TablaEquipos[Team],0)) -> #VALUE! | G8: 0 | H8: 0 | J8: =INDEX(TablaEquipos[Badge],MATCH(K8,TablaEquipos[Team],0)) -> #VALUE! | K8: Pafos | N8: 7 | O8: =INDEX(TablaEquipos[],MATCH(P8,TablaEquipos[Team],0),MATCH($O$1,TablaEquipos[#Headers],0)) -> #VALUE! | P8: =IFERROR(INDEX(Calcs!A$2:A$37,MATCH($N8,Calcs!$CJ$2:$CJ$37,0)),"") -> Newcastle | Q8: =IFERROR(INDEX(Calcs!$B$2:$AB$37,MATCH($N8,Calcs!$CJ$2:$CJ$37,0),MATCH(Q$1,Calcs!$B$1:$AB$1,0)),"") -> 13 | R8: =IFERROR(INDEX(Calcs!$B$2:$AB$37,MATCH($N8,Calcs!$CJ$2:$CJ$37,0),MATCH(R$1,Calcs!$B$1:$AB$1,0)),"") -> 7 | S8: =IFERROR(INDEX(Calcs!$B$2:$AB$37,MATCH($N8,Calcs!$CJ$2:$CJ$37,0),MATCH(S$1,Calcs!$B$1:$AB$1,0)),"") -> 4 | T8: =IFERROR(INDEX(Calcs!$B$2:$AB$37,MATCH($N8,Calcs!$CJ$2:$CJ$37,0),MATCH(T$1,Calcs!$B$1:$AB$1,0)),"") -> 1 | U8: =IFERROR(INDEX(Calcs!$B$2:$AB$37,MATCH($N8,Calcs!$CJ$2:$CJ$37,0),MATCH(U$1,Calcs!$B$1:$AB$1,0)),"") -> 2 | V8: =IFERROR(INDEX(Calcs!$B$2:$AB$37,MATCH($N8,Calcs!$CJ$2:$CJ$37,0),MATCH(V$1,Calcs!$B$1:$AB$1,0)),"") -> 16 | W8: =IFERROR(INDEX(Calcs!$B$2:$AB$37,MATCH($N8,Calcs!$CJ$2:$CJ$37,0),MATCH(W$1,Calcs!$B$1:$AB$1,0)),"") -> 6 | X8: =IFERROR(INDEX(Calcs!$B$2:$AB$37,MATCH($N8,Calcs!$CJ$2:$CJ$37,0),MATCH(X$1,Calcs!$B$1:$AB$1,0)),"") -> 10 | ... AQ8: =IFERROR(INDEX(Calcs!$B$2:$AB$37,MATCH($N8,Calcs!$CJ$2:$CJ$37,0),MATCH(AQ$1,Calcs!$B$1:$AB$1,0)),"") -> 94 | AS8: =INDEX(Calcs!A$2:A$37,MATCH($N8,Calcs!$CF$2:$CF$37,0)) -> Newcastle | AU8: =INDEX(Calcs!$BZ$2:$BZ$37,MATCH($AS8,Calcs!$A$2:$A$37,0)) -> 7 | AV8: =COUNTIF($AU$2:$AU$37,$AU8) -> 1 | AW8: =AU8&"."&AV8 -> 7.1 | AZ8: =TablaEquipos[[#This Row],[Team]] -> Bayer Leverkusen | BF8: =IF(OR(G8="",H8=""),"Pendiente",IF(G8>H8,"Local",IF(G8<H8,"Visitante","Empate"))) -> Empate | BH8: 7 | BI8: {=IFERROR(INDEX(Equipo_visitante,MATCH($BH8&BI$1,Jornada&Equipo_local,0)),INDEX(Equipo_local,MATCH($BH8&BI$1,Jornada&Equipo_visitante,0)))} -> Villarreal | BJ8: {=IFERROR(INDEX(Equipo_visitante,MATCH($BH8&BJ$1,Jornada&Equipo_local,0)),INDEX(Equipo_local,MATCH($BH8&BJ$1,Jornada&Equipo_visitante,0)))} -> Inter Milan | BK8: {=IFERROR(INDEX(Equipo_visitante,MATCH($BH8&BK$1,Jornada&Equipo_local,0)),INDEX(Equipo_local,MATCH($BH8&BK$1,Jornada&Equipo_visitante,0)))} -> Athletic Bilbao | BL8: {=IFERROR(INDEX(Equipo_visitante,MATCH($BH8&BL$1,Jornada&Equipo_local,0)),INDEX(Equipo_local,MATCH($BH8&BL$1,Jornada&Equipo_visitante,0)))} -> Atalanta | BM8: {=IFERROR(INDEX(Equipo_visitante,MATCH($BH8&BM$1,Jornada&Equipo_local,0)),INDEX(Equipo_local,MATCH($BH8&BM$1,Jornada&Equipo_visitante,0)))} -> Galatasaray | BN8: {=IFERROR(INDEX(Equipo_visitante,MATCH($BH8&BN$1,Jornada&Equipo_local,0)),INDEX(Equipo_local,MATCH($BH8&BN$1,Jornada&Equipo_visitante,0)))} -> Slavia Praha | BO8: {=IFERROR(INDEX(Equipo_visitante,MATCH($BH8&BO$1,Jornada&Equipo_local,0)),INDEX(Equipo_local,MATCH($BH8&BO$1,Jornada&Equipo_visitante,0)))} -> Olympiakos | BP8: {=IFERROR(INDEX(Equipo_visitante,MATCH($BH8&BP$1,Jornada&Equipo_local,0)),INDEX(Equipo_local,MATCH($BH8&BP$1,Jornada&Equipo_visitante,0)))} -> Union Saint-Gilloise | ... CR8: {=IFERROR(INDEX(Equipo_visitante,MATCH($BH8&CR$1,Jornada&Equipo_local,0)),INDEX(Equipo_local,MATCH($BH8&CR$1,Jornada&Equipo_visitante,0)))} -> Ajax
A9: 1 | B9: =Horarios!C9 -> 45917.781 | C9: =Horarios!C9 -> 45917.781 | D9: Slavia Praha | E9: =INDEX(TablaEquipos[Badge],MATCH(D9,TablaEquipos[Team],0)) -> #VALUE! | G9: 2 | H9: 2 | J9: =INDEX(TablaEquipos[Badge],MATCH(K9,TablaEquipos[Team],0)) -> #VALUE! | K9: Bodø/Glimt | N9: 8 | O9: =INDEX(TablaEquipos[],MATCH(P9,TablaEquipos[Team],0),MATCH($O$1,TablaEquipos[#Headers],0)) -> #VALUE! | P9: =IFERROR(INDEX(Calcs!A$2:A$37,MATCH($N9,Calcs!$CJ$2:$CJ$37,0)),"") -> Chelsea | Q9: =IFERROR(INDEX(Calcs!$B$2:$AB$37,MATCH($N9,Calcs!$CJ$2:$CJ$37,0),MATCH(Q$1,Calcs!$B$1:$AB$1,0)),"") -> 13 | R9: =IFERROR(INDEX(Calcs!$B$2:$AB$37,MATCH($N9,Calcs!$CJ$2:$CJ$37,0),MATCH(R$1,Calcs!$B$1:$AB$1,0)),"") -> 7 | S9: =IFERROR(INDEX(Calcs!$B$2:$AB$37,MATCH($N9,Calcs!$CJ$2:$CJ$37,0),MATCH(S$1,Calcs!$B$1:$AB$1,0)),"") -> 4 | T9: =IFERROR(INDEX(Calcs!$B$2:$AB$37,MATCH($N9,Calcs!$CJ$2:$CJ$37,0),MATCH(T$1,Calcs!$B$1:$AB$1,0)),"") -> 1 | U9: =IFERROR(INDEX(Calcs!$B$2:$AB$37,MATCH($N9,Calcs!$CJ$2:$CJ$37,0),MATCH(U$1,Calcs!$B$1:$AB$1,0)),"") -> 2 | V9: =IFERROR(INDEX(Calcs!$B$2:$AB$37,MATCH($N9,Calcs!$CJ$2:$CJ$37,0),MATCH(V$1,Calcs!$B$1:$AB$1,0)),"") -> 14 | W9: =IFERROR(INDEX(Calcs!$B$2:$AB$37,MATCH($N9,Calcs!$CJ$2:$CJ$37,0),MATCH(W$1,Calcs!$B$1:$AB$1,0)),"") -> 8 | X9: =IFERROR(INDEX(Calcs!$B$2:$AB$37,MATCH($N9,Calcs!$CJ$2:$CJ$37,0),MATCH(X$1,Calcs!$B$1:$AB$1,0)),"") -> 6 | ... AQ9: =IFERROR(INDEX(Calcs!$B$2:$AB$37,MATCH($N9,Calcs!$CJ$2:$CJ$37,0),MATCH(AQ$1,Calcs!$B$1:$AB$1,0)),"") -> 85 | AS9: =INDEX(Calcs!A$2:A$37,MATCH($N9,Calcs!$CF$2:$CF$37,0)) -> Chelsea | AU9: =INDEX(Calcs!$BZ$2:$BZ$37,MATCH($AS9,Calcs!$A$2:$A$37,0)) -> 8 | AV9: =COUNTIF($AU$2:$AU$37,$AU9) -> 1 | AW9: =AU9&"."&AV9 -> 8.1 | AZ9: =TablaEquipos[[#This Row],[Team]] -> Bayern München | BF9: =IF(OR(G9="",H9=""),"Pendiente",IF(G9>H9,"Local",IF(G9<H9,"Visitante","Empate"))) -> Empate | BH9: 8 | BI9: {=IFERROR(INDEX(Equipo_visitante,MATCH($BH9&BI$1,Jornada&Equipo_local,0)),INDEX(Equipo_local,MATCH($BH9&BI$1,Jornada&Equipo_visitante,0)))} -> Olympiakos | BJ9: {=IFERROR(INDEX(Equipo_visitante,MATCH($BH9&BJ$1,Jornada&Equipo_local,0)),INDEX(Equipo_local,MATCH($BH9&BJ$1,Jornada&Equipo_visitante,0)))} -> Kairat Almaty | BK9: {=IFERROR(INDEX(Equipo_visitante,MATCH($BH9&BK$1,Jornada&Equipo_local,0)),INDEX(Equipo_local,MATCH($BH9&BK$1,Jornada&Equipo_visitante,0)))} -> Union Saint-Gilloise | BL9: {=IFERROR(INDEX(Equipo_visitante,MATCH($BH9&BL$1,Jornada&Equipo_local,0)),INDEX(Equipo_local,MATCH($BH9&BL$1,Jornada&Equipo_visitante,0)))} -> Sporting Portugal | BM9: {=IFERROR(INDEX(Equipo_visitante,MATCH($BH9&BM$1,Jornada&Equipo_local,0)),INDEX(Equipo_local,MATCH($BH9&BM$1,Jornada&Equipo_visitante,0)))} -> Bodø/Glimt | BN9: {=IFERROR(INDEX(Equipo_visitante,MATCH($BH9&BN$1,Jornada&Equipo_local,0)),INDEX(Equipo_local,MATCH($BH9&BN$1,Jornada&Equipo_visitante,0)))} -> Copenhagen | BO9: {=IFERROR(INDEX(Equipo_visitante,MATCH($BH9&BO$1,Jornada&Equipo_local,0)),INDEX(Equipo_local,MATCH($BH9&BO$1,Jornada&Equipo_visitante,0)))} -> Villarreal | BP9: {=IFERROR(INDEX(Equipo_visitante,MATCH($BH9&BP$1,Jornada&Equipo_local,0)),INDEX(Equipo_local,MATCH($BH9&BP$1,Jornada&Equipo_visitante,0)))} -> PSV Eindhoven | ... CR9: {=IFERROR(INDEX(Equipo_visitante,MATCH($BH9&CR$1,Jornada&Equipo_local,0)),INDEX(Equipo_local,MATCH($BH9&CR$1,Jornada&Equipo_visitante,0)))} -> Bayer Leverkusen
A10: 1 | B10: =Horarios!C10 -> 45917.875 | C10: =Horarios!C10 -> 45917.875 | D10: Ajax | E10: =INDEX(TablaEquipos[Badge],MATCH(D10,TablaEquipos[Team],0)) -> #VALUE! | G10: 0 | H10: 2 | J10: =INDEX(TablaEquipos[Badge],MATCH(K10,TablaEquipos[Team],0)) -> #VALUE! | K10: Inter Milan | N10: 9 | O10: =INDEX(TablaEquipos[],MATCH(P10,TablaEquipos[Team],0),MATCH($O$1,TablaEquipos[#Headers],0)) -> #VALUE! | P10: =IFERROR(INDEX(Calcs!A$2:A$37,MATCH($N10,Calcs!$CJ$2:$CJ$37,0)),"") -> Barcelona | Q10: =IFERROR(INDEX(Calcs!$B$2:$AB$37,MATCH($N10,Calcs!$CJ$2:$CJ$37,0),MATCH(Q$1,Calcs!$B$1:$AB$1,0)),"") -> 13 | R10: =IFERROR(INDEX(Calcs!$B$2:$AB$37,MATCH($N10,Calcs!$CJ$2:$CJ$37,0),MATCH(R$1,Calcs!$B$1:$AB$1,0)),"") -> 7 | S10: =IFERROR(INDEX(Calcs!$B$2:$AB$37,MATCH($N10,Calcs!$CJ$2:$CJ$37,0),MATCH(S$1,Calcs!$B$1:$AB$1,0)),"") -> 4 | T10: =IFERROR(INDEX(Calcs!$B$2:$AB$37,MATCH($N10,Calcs!$CJ$2:$CJ$37,0),MATCH(T$1,Calcs!$B$1:$AB$1,0)),"") -> 1 | U10: =IFERROR(INDEX(Calcs!$B$2:$AB$37,MATCH($N10,Calcs!$CJ$2:$CJ$37,0),MATCH(U$1,Calcs!$B$1:$AB$1,0)),"") -> 2 | V10: =IFERROR(INDEX(Calcs!$B$2:$AB$37,MATCH($N10,Calcs!$CJ$2:$CJ$37,0),MATCH(V$1,Calcs!$B$1:$AB$1,0)),"") -> 18 | W10: =IFERROR(INDEX(Calcs!$B$2:$AB$37,MATCH($N10,Calcs!$CJ$2:$CJ$37,0),MATCH(W$1,Calcs!$B$1:$AB$1,0)),"") -> 13 | X10: =IFERROR(INDEX(Calcs!$B$2:$AB$37,MATCH($N10,Calcs!$CJ$2:$CJ$37,0),MATCH(X$1,Calcs!$B$1:$AB$1,0)),"") -> 5 | ... AQ10: =IFERROR(INDEX(Calcs!$B$2:$AB$37,MATCH($N10,Calcs!$CJ$2:$CJ$37,0),MATCH(AQ$1,Calcs!$B$1:$AB$1,0)),"") -> 95 | AS10: =INDEX(Calcs!A$2:A$37,MATCH($N10,Calcs!$CF$2:$CF$37,0)) -> Barcelona | AU10: =INDEX(Calcs!$BZ$2:$BZ$37,MATCH($AS10,Calcs!$A$2:$A$37,0)) -> 9 | AV10: =COUNTIF($AU$2:$AU$37,$AU10) -> 1 | AW10: =AU10&"."&AV10 -> 9.1 | AZ10: =TablaEquipos[[#This Row],[Team]] -> Benfica | BF10: =IF(OR(G10="",H10=""),"Pendiente",IF(G10>H10,"Local",IF(G10<H10,"Visitante","Empate"))) -> Visitante | BH10: Puntos | BI10: =SUMIF(Calcs!$A$2:$A$37,League!BI2,Calcs!$I$2:$I$37)-INDEX($BA$2:$BA$37,MATCH(BI2,$AZ$2:$AZ$37,0)) -> 12 | BJ10: =SUMIF(Calcs!$A$2:$A$37,League!BJ2,Calcs!$I$2:$I$37)-INDEX($BA$2:$BA$37,MATCH(BJ2,$AZ$2:$AZ$37,0)) -> 8 | BK10: =SUMIF(Calcs!$A$2:$A$37,League!BK2,Calcs!$I$2:$I$37)-INDEX($BA$2:$BA$37,MATCH(BK2,$AZ$2:$AZ$37,0)) -> 13 | BL10: =SUMIF(Calcs!$A$2:$A$37,League!BL2,Calcs!$I$2:$I$37)-INDEX($BA$2:$BA$37,MATCH(BL2,$AZ$2:$AZ$37,0)) -> 21 | BM10: =SUMIF(Calcs!$A$2:$A$37,League!BM2,Calcs!$I$2:$I$37)-INDEX($BA$2:$BA$37,MATCH(BM2,$AZ$2:$AZ$37,0)) -> 15 | BN10: =SUMIF(Calcs!$A$2:$A$37,League!BN2,Calcs!$I$2:$I$37)-INDEX($BA$2:$BA$37,MATCH(BN2,$AZ$2:$AZ$37,0)) -> 13 | BO10: =SUMIF(Calcs!$A$2:$A$37,League!BO2,Calcs!$I$2:$I$37)-INDEX($BA$2:$BA$37,MATCH(BO2,$AZ$2:$AZ$37,0)) -> 8 | BP10: =SUMIF(Calcs!$A$2:$A$37,League!BP2,Calcs!$I$2:$I$37)-INDEX($BA$2:$BA$37,MATCH(BP2,$AZ$2:$AZ$37,0)) -> 13 | ... CR10: =SUMIF(Calcs!$A$2:$A$37,League!CR2,Calcs!$I$2:$I$37)-INDEX($BA$2:$BA$37,MATCH(CR2,$AZ$2:$AZ$37,0)) -> 14
A11: 1 | B11: =Horarios!C11 -> 45917.875 | C11: =Horarios!C11 -> 45917.875 | D11: Bayern München | E11: =INDEX(TablaEquipos[Badge],MATCH(D11,TablaEquipos[Team],0)) -> #VALUE! | G11: 3 | H11: 1 | J11: =INDEX(TablaEquipos[Badge],MATCH(K11,TablaEquipos[Team],0)) -> #VALUE! | K11: Chelsea | N11: 10 | O11: =INDEX(TablaEquipos[],MATCH(P11,TablaEquipos[Team],0),MATCH($O$1,TablaEquipos[#Headers],0)) -> #VALUE! | P11: =IFERROR(INDEX(Calcs!A$2:A$37,MATCH($N11,Calcs!$CJ$2:$CJ$37,0)),"") -> Sporting Portugal | Q11: =IFERROR(INDEX(Calcs!$B$2:$AB$37,MATCH($N11,Calcs!$CJ$2:$CJ$37,0),MATCH(Q$1,Calcs!$B$1:$AB$1,0)),"") -> 13 | R11: =IFERROR(INDEX(Calcs!$B$2:$AB$37,MATCH($N11,Calcs!$CJ$2:$CJ$37,0),MATCH(R$1,Calcs!$B$1:$AB$1,0)),"") -> 7 | S11: =IFERROR(INDEX(Calcs!$B$2:$AB$37,MATCH($N11,Calcs!$CJ$2:$CJ$37,0),MATCH(S$1,Calcs!$B$1:$AB$1,0)),"") -> 4 | T11: =IFERROR(INDEX(Calcs!$B$2:$AB$37,MATCH($N11,Calcs!$CJ$2:$CJ$37,0),MATCH(T$1,Calcs!$B$1:$AB$1,0)),"") -> 1 | U11: =IFERROR(INDEX(Calcs!$B$2:$AB$37,MATCH($N11,Calcs!$CJ$2:$CJ$37,0),MATCH(U$1,Calcs!$B$1:$AB$1,0)),"") -> 2 | V11: =IFERROR(INDEX(Calcs!$B$2:$AB$37,MATCH($N11,Calcs!$CJ$2:$CJ$37,0),MATCH(V$1,Calcs!$B$1:$AB$1,0)),"") -> 14 | W11: =IFERROR(INDEX(Calcs!$B$2:$AB$37,MATCH($N11,Calcs!$CJ$2:$CJ$37,0),MATCH(W$1,Calcs!$B$1:$AB$1,0)),"") -> 9 | X11: =IFERROR(INDEX(Calcs!$B$2:$AB$37,MATCH($N11,Calcs!$CJ$2:$CJ$37,0),MATCH(X$1,Calcs!$B$1:$AB$1,0)),"") -> 5 | ... AQ11: =IFERROR(INDEX(Calcs!$B$2:$AB$37,MATCH($N11,Calcs!$CJ$2:$CJ$37,0),MATCH(AQ$1,Calcs!$B$1:$AB$1,0)),"") -> 96 | AS11: =INDEX(Calcs!A$2:A$37,MATCH($N11,Calcs!$CF$2:$CF$37,0)) -> Sporting Portugal | AU11: =INDEX(Calcs!$BZ$2:$BZ$37,MATCH($AS11,Calcs!$A$2:$A$37,0)) -> 10 | AV11: =COUNTIF($AU$2:$AU$37,$AU11) -> 1 | AW11: =AU11&"."&AV11 -> 10.1 | AZ11: =TablaEquipos[[#This Row],[Team]] -> Bodø/Glimt | BF11: =IF(OR(G11="",H11=""),"Pendiente",IF(G11>H11,"Local",IF(G11<H11,"Visitante","Empate"))) -> Local | BI11: =SUMIF(Calcs!$A$2:$A$37,League!BI3,Calcs!$I$2:$I$37)-INDEX($BA$2:$BA$37,MATCH(BI3,$AZ$2:$AZ$37,0)) -> 9 | BJ11: =SUMIF(Calcs!$A$2:$A$37,League!BJ3,Calcs!$I$2:$I$37)-INDEX($BA$2:$BA$37,MATCH(BJ3,$AZ$2:$AZ$37,0)) -> 8 | BK11: =SUMIF(Calcs!$A$2:$A$37,League!BK3,Calcs!$I$2:$I$37)-INDEX($BA$2:$BA$37,MATCH(BK3,$AZ$2:$AZ$37,0)) -> 7 | BL11: =SUMIF(Calcs!$A$2:$A$37,League!BL3,Calcs!$I$2:$I$37)-INDEX($BA$2:$BA$37,MATCH(BL3,$AZ$2:$AZ$37,0)) -> 11 | BM11: =SUMIF(Calcs!$A$2:$A$37,League!BM3,Calcs!$I$2:$I$37)-INDEX($BA$2:$BA$37,MATCH(BM3,$AZ$2:$AZ$37,0)) -> 4 | BN11: =SUMIF(Calcs!$A$2:$A$37,League!BN3,Calcs!$I$2:$I$37)-INDEX($BA$2:$BA$37,MATCH(BN3,$AZ$2:$AZ$37,0)) -> 13 | BO11: =SUMIF(Calcs!$A$2:$A$37,League!BO3,Calcs!$I$2:$I$37)-INDEX($BA$2:$BA$37,MATCH(BO3,$AZ$2:$AZ$37,0)) -> 8 | BP11: =SUMIF(Calcs!$A$2:$A$37,League!BP3,Calcs!$I$2:$I$37)-INDEX($BA$2:$BA$37,MATCH(BP3,$AZ$2:$AZ$37,0)) -> 6 | ... CR11: =SUMIF(Calcs!$A$2:$A$37,League!CR3,Calcs!$I$2:$I$37)-INDEX($BA$2:$BA$37,MATCH(CR3,$AZ$2:$AZ$37,0)) -> 12
A12: 1 | B12: =Horarios!C12 -> 45917.875 | C12: =Horarios!C12 -> 45917.875 | D12: Liverpool | E12: =INDEX(TablaEquipos[Badge],MATCH(D12,TablaEquipos[Team],0)) -> #VALUE! | G12: 3 | H12: 2 | J12: =INDEX(TablaEquipos[Badge],MATCH(K12,TablaEquipos[Team],0)) -> #VALUE! | K12: Atlético Madrid | N12: 11 | O12: =INDEX(TablaEquipos[],MATCH(P12,TablaEquipos[Team],0),MATCH($O$1,TablaEquipos[#Headers],0)) -> #VALUE! | P12: =IFERROR(INDEX(Calcs!A$2:A$37,MATCH($N12,Calcs!$CJ$2:$CJ$37,0)),"") -> Manchester City | Q12: =IFERROR(INDEX(Calcs!$B$2:$AB$37,MATCH($N12,Calcs!$CJ$2:$CJ$37,0),MATCH(Q$1,Calcs!$B$1:$AB$1,0)),"") -> 13 | R12: =IFERROR(INDEX(Calcs!$B$2:$AB$37,MATCH($N12,Calcs!$CJ$2:$CJ$37,0),MATCH(R$1,Calcs!$B$1:$AB$1,0)),"") -> 7 | S12: =IFERROR(INDEX(Calcs!$B$2:$AB$37,MATCH($N12,Calcs!$CJ$2:$CJ$37,0),MATCH(S$1,Calcs!$B$1:$AB$1,0)),"") -> 4 | T12: =IFERROR(INDEX(Calcs!$B$2:$AB$37,MATCH($N12,Calcs!$CJ$2:$CJ$37,0),MATCH(T$1,Calcs!$B$1:$AB$1,0)),"") -> 1 | U12: =IFERROR(INDEX(Calcs!$B$2:$AB$37,MATCH($N12,Calcs!$CJ$2:$CJ$37,0),MATCH(U$1,Calcs!$B$1:$AB$1,0)),"") -> 2 | V12: =IFERROR(INDEX(Calcs!$B$2:$AB$37,MATCH($N12,Calcs!$CJ$2:$CJ$37,0),MATCH(V$1,Calcs!$B$1:$AB$1,0)),"") -> 13 | W12: =IFERROR(INDEX(Calcs!$B$2:$AB$37,MATCH($N12,Calcs!$CJ$2:$CJ$37,0),MATCH(W$1,Calcs!$B$1:$AB$1,0)),"") -> 9 | X12: =IFERROR(INDEX(Calcs!$B$2:$AB$37,MATCH($N12,Calcs!$CJ$2:$CJ$37,0),MATCH(X$1,Calcs!$B$1:$AB$1,0)),"") -> 4 | ... AQ12: =IFERROR(INDEX(Calcs!$B$2:$AB$37,MATCH($N12,Calcs!$CJ$2:$CJ$37,0),MATCH(AQ$1,Calcs!$B$1:$AB$1,0)),"") -> 89 | AS12: =INDEX(Calcs!A$2:A$37,MATCH($N12,Calcs!$CF$2:$CF$37,0)) -> Manchester City | AU12: =INDEX(Calcs!$BZ$2:$BZ$37,MATCH($AS12,Calcs!$A$2:$A$37,0)) -> 11 | AV12: =COUNTIF($AU$2:$AU$37,$AU12) -> 1 | AW12: =AU12&"."&AV12 -> 11.1 | AZ12: =TablaEquipos[[#This Row],[Team]] -> Borussia Dortmund | BF12: =IF(OR(G12="",H12=""),"Pendiente",IF(G12>H12,"Local",IF(G12<H12,"Visitante","Empate"))) -> Local | BI12: =SUMIF(Calcs!$A$2:$A$37,League!BI4,Calcs!$I$2:$I$37)-INDEX($BA$2:$BA$37,MATCH(BI4,$AZ$2:$AZ$37,0)) -> 13 | BJ12: =SUMIF(Calcs!$A$2:$A$37,League!BJ4,Calcs!$I$2:$I$37)-INDEX($BA$2:$BA$37,MATCH(BJ4,$AZ$2:$AZ$37,0)) -> 13 | BK12: =SUMIF(Calcs!$A$2:$A$37,League!BK4,Calcs!$I$2:$I$37)-INDEX($BA$2:$BA$37,MATCH(BK4,$AZ$2:$AZ$37,0)) -> 3 | BL12: =SUMIF(Calcs!$A$2:$A$37,League!BL4,Calcs!$I$2:$I$37)-INDEX($BA$2:$BA$37,MATCH(BL4,$AZ$2:$AZ$37,0)) -> 10 | BM12: =SUMIF(Calcs!$A$2:$A$37,League!BM4,Calcs!$I$2:$I$37)-INDEX($BA$2:$BA$37,MATCH(BM4,$AZ$2:$AZ$37,0)) -> 21 | BN12: =SUMIF(Calcs!$A$2:$A$37,League!BN4,Calcs!$I$2:$I$37)-INDEX($BA$2:$BA$37,MATCH(BN4,$AZ$2:$AZ$37,0)) -> 8 | BO12: =SUMIF(Calcs!$A$2:$A$37,League!BO4,Calcs!$I$2:$I$37)-INDEX($BA$2:$BA$37,MATCH(BO4,$AZ$2:$AZ$37,0)) -> 13 | BP12: =SUMIF(Calcs!$A$2:$A$37,League!BP4,Calcs!$I$2:$I$37)-INDEX($BA$2:$BA$37,MATCH(BP4,$AZ$2:$AZ$37,0)) -> 7 | ... CR12: =SUMIF(Calcs!$A$2:$A$37,League!CR4,Calcs!$I$2:$I$37)-INDEX($BA$2:$BA$37,MATCH(CR4,$AZ$2:$AZ$37,0)) -> 13
A13: 1 | B13: =Horarios!C13 -> 45917.875 | C13: =Horarios!C13 -> 45917.875 | D13: PSG | E13: =INDEX(TablaEquipos[Badge],MATCH(D13,TablaEquipos[Team],0)) -> #VALUE! | G13: 4 | H13: 0 | J13: =INDEX(TablaEquipos[Badge],MATCH(K13,TablaEquipos[Team],0)) -> #VALUE! | K13: Atalanta | N13: 12 | O13: =INDEX(TablaEquipos[],MATCH(P13,TablaEquipos[Team],0),MATCH($O$1,TablaEquipos[#Headers],0)) -> #VALUE! | P13: =IFERROR(INDEX(Calcs!A$2:A$37,MATCH($N13,Calcs!$CJ$2:$CJ$37,0)),"") -> Atlético Madrid | Q13: =IFERROR(INDEX(Calcs!$B$2:$AB$37,MATCH($N13,Calcs!$CJ$2:$CJ$37,0),MATCH(Q$1,Calcs!$B$1:$AB$1,0)),"") -> 13 | R13: =IFERROR(INDEX(Calcs!$B$2:$AB$37,MATCH($N13,Calcs!$CJ$2:$CJ$37,0),MATCH(R$1,Calcs!$B$1:$AB$1,0)),"") -> 7 | S13: =IFERROR(INDEX(Calcs!$B$2:$AB$37,MATCH($N13,Calcs!$CJ$2:$CJ$37,0),MATCH(S$1,Calcs!$B$1:$AB$1,0)),"") -> 4 | T13: =IFERROR(INDEX(Calcs!$B$2:$AB$37,MATCH($N13,Calcs!$CJ$2:$CJ$37,0),MATCH(T$1,Calcs!$B$1:$AB$1,0)),"") -> 1 | U13: =IFERROR(INDEX(Calcs!$B$2:$AB$37,MATCH($N13,Calcs!$CJ$2:$CJ$37,0),MATCH(U$1,Calcs!$B$1:$AB$1,0)),"") -> 2 | V13: =IFERROR(INDEX(Calcs!$B$2:$AB$37,MATCH($N13,Calcs!$CJ$2:$CJ$37,0),MATCH(V$1,Calcs!$B$1:$AB$1,0)),"") -> 16 | W13: =IFERROR(INDEX(Calcs!$B$2:$AB$37,MATCH($N13,Calcs!$CJ$2:$CJ$37,0),MATCH(W$1,Calcs!$B$1:$AB$1,0)),"") -> 13 | X13: =IFERROR(INDEX(Calcs!$B$2:$AB$37,MATCH($N13,Calcs!$CJ$2:$CJ$37,0),MATCH(X$1,Calcs!$B$1:$AB$1,0)),"") -> 3 | ... AQ13: =IFERROR(INDEX(Calcs!$B$2:$AB$37,MATCH($N13,Calcs!$CJ$2:$CJ$37,0),MATCH(AQ$1,Calcs!$B$1:$AB$1,0)),"") -> 100 | AS13: =INDEX(Calcs!A$2:A$37,MATCH($N13,Calcs!$CF$2:$CF$37,0)) -> Atlético Madrid | AU13: =INDEX(Calcs!$BZ$2:$BZ$37,MATCH($AS13,Calcs!$A$2:$A$37,0)) -> 12 | AV13: =COUNTIF($AU$2:$AU$37,$AU13) -> 1 | AW13: =AU13&"."&AV13 -> 12.1 | AZ13: =TablaEquipos[[#This Row],[Team]] -> Brugge | BF13: =IF(OR(G13="",H13=""),"Pendiente",IF(G13>H13,"Local",IF(G13<H13,"Visitante","Empate"))) -> Local | BI13: =SUMIF(Calcs!$A$2:$A$37,League!BI5,Calcs!$I$2:$I$37)-INDEX($BA$2:$BA$37,MATCH(BI5,$AZ$2:$AZ$37,0)) -> 10 | BJ13: =SUMIF(Calcs!$A$2:$A$37,League!BJ5,Calcs!$I$2:$I$37)-INDEX($BA$2:$BA$37,MATCH(BJ5,$AZ$2:$AZ$37,0)) -> 3 | BK13: =SUMIF(Calcs!$A$2:$A$37,League!BK5,Calcs!$I$2:$I$37)-INDEX($BA$2:$BA$37,MATCH(BK5,$AZ$2:$AZ$37,0)) -> 9 | BL13: =SUMIF(Calcs!$A$2:$A$37,League!BL5,Calcs!$I$2:$I$37)-INDEX($BA$2:$BA$37,MATCH(BL5,$AZ$2:$AZ$37,0)) -> 13 | BM13: =SUMIF(Calcs!$A$2:$A$37,League!BM5,Calcs!$I$2:$I$37)-INDEX($BA$2:$BA$37,MATCH(BM5,$AZ$2:$AZ$37,0)) -> 6 | BN13: =SUMIF(Calcs!$A$2:$A$37,League!BN5,Calcs!$I$2:$I$37)-INDEX($BA$2:$BA$37,MATCH(BN5,$AZ$2:$AZ$37,0)) -> 7 | BO13: =SUMIF(Calcs!$A$2:$A$37,League!BO5,Calcs!$I$2:$I$37)-INDEX($BA$2:$BA$37,MATCH(BO5,$AZ$2:$AZ$37,0)) -> 6 | BP13: =SUMIF(Calcs!$A$2:$A$37,League!BP5,Calcs!$I$2:$I$37)-INDEX($BA$2:$BA$37,MATCH(BP5,$AZ$2:$AZ$37,0)) -> 13 | ... CR13: =SUMIF(Calcs!$A$2:$A$37,League!CR5,Calcs!$I$2:$I$37)-INDEX($BA$2:$BA$37,MATCH(CR5,$AZ$2:$AZ$37,0)) -> 6
A14: 1 | B14: =Horarios!C14 -> 45918.781 | C14: =Horarios!C14 -> 45918.781 | D14: Brugge | E14: =INDEX(TablaEquipos[Badge],MATCH(D14,TablaEquipos[Team],0)) -> #VALUE! | G14: 4 | H14: 1 | J14: #VALUE! | K14: Monaco | N14: 13 | O14: =INDEX(TablaEquipos[],MATCH(P14,TablaEquipos[Team],0),MATCH($O$1,TablaEquipos[#Headers],0)) -> #VALUE! | P14: =IFERROR(INDEX(Calcs!A$2:A$37,MATCH($N14,Calcs!$CJ$2:$CJ$37,0)),"") -> Atalanta | Q14: =IFERROR(INDEX(Calcs!$B$2:$AB$37,MATCH($N14,Calcs!$CJ$2:$CJ$37,0),MATCH(Q$1,Calcs!$B$1:$AB$1,0)),"") -> 13 | R14: =IFERROR(INDEX(Calcs!$B$2:$AB$37,MATCH($N14,Calcs!$CJ$2:$CJ$37,0),MATCH(R$1,Calcs!$B$1:$AB$1,0)),"") -> 7 | S14: =IFERROR(INDEX(Calcs!$B$2:$AB$37,MATCH($N14,Calcs!$CJ$2:$CJ$37,0),MATCH(S$1,Calcs!$B$1:$AB$1,0)),"") -> 4 | T14: =IFERROR(INDEX(Calcs!$B$2:$AB$37,MATCH($N14,Calcs!$CJ$2:$CJ$37,0),MATCH(T$1,Calcs!$B$1:$AB$1,0)),"") -> 1 | U14: =IFERROR(INDEX(Calcs!$B$2:$AB$37,MATCH($N14,Calcs!$CJ$2:$CJ$37,0),MATCH(U$1,Calcs!$B$1:$AB$1,0)),"") -> 2 | V14: =IFERROR(INDEX(Calcs!$B$2:$AB$37,MATCH($N14,Calcs!$CJ$2:$CJ$37,0),MATCH(V$1,Calcs!$B$1:$AB$1,0)),"") -> 10 | W14: =IFERROR(INDEX(Calcs!$B$2:$AB$37,MATCH($N14,Calcs!$CJ$2:$CJ$37,0),MATCH(W$1,Calcs!$B$1:$AB$1,0)),"") -> 9 | X14: =IFERROR(INDEX(Calcs!$B$2:$AB$37,MATCH($N14,Calcs!$CJ$2:$CJ$37,0),MATCH(X$1,Calcs!$B$1:$AB$1,0)),"") -> 1 | ... AQ14: =IFERROR(INDEX(Calcs!$B$2:$AB$37,MATCH($N14,Calcs!$CJ$2:$CJ$37,0),MATCH(AQ$1,Calcs!$B$1:$AB$1,0)),"") -> 85 | AS14: =INDEX(Calcs!A$2:A$37,MATCH($N14,Calcs!$CF$2:$CF$37,0)) -> Atalanta | AU14: =INDEX(Calcs!$BZ$2:$BZ$37,MATCH($AS14,Calcs!$A$2:$A$37,0)) -> 13 | AV14: =COUNTIF($AU$2:$AU$37,$AU14) -> 1 | AW14: =AU14&"."&AV14 -> 13.1 | AZ14: =TablaEquipos[[#This Row],[Team]] -> Chelsea | BF14: =IF(OR(G14="",H14=""),"Pendiente",IF(G14>H14,"Local",IF(G14<H14,"Visitante","Empate"))) -> Local | BI14: =SUMIF(Calcs!$A$2:$A$37,League!BI6,Calcs!$I$2:$I$37)-INDEX($BA$2:$BA$37,MATCH(BI6,$AZ$2:$AZ$37,0)) -> 6 | BJ14: =SUMIF(Calcs!$A$2:$A$37,League!BJ6,Calcs!$I$2:$I$37)-INDEX($BA$2:$BA$37,MATCH(BJ6,$AZ$2:$AZ$37,0)) -> 18 | BK14: =SUMIF(Calcs!$A$2:$A$37,League!BK6,Calcs!$I$2:$I$37)-INDEX($BA$2:$BA$37,MATCH(BK6,$AZ$2:$AZ$37,0)) -> 4 | BL14: =SUMIF(Calcs!$A$2:$A$37,League!BL6,Calcs!$I$2:$I$37)-INDEX($BA$2:$BA$37,MATCH(BL6,$AZ$2:$AZ$37,0)) -> 3 | BM14: =SUMIF(Calcs!$A$2:$A$37,League!BM6,Calcs!$I$2:$I$37)-INDEX($BA$2:$BA$37,MATCH(BM6,$AZ$2:$AZ$37,0)) -> 12 | BN14: =SUMIF(Calcs!$A$2:$A$37,League!BN6,Calcs!$I$2:$I$37)-INDEX($BA$2:$BA$37,MATCH(BN6,$AZ$2:$AZ$37,0)) -> 13 | BO14: =SUMIF(Calcs!$A$2:$A$37,League!BO6,Calcs!$I$2:$I$37)-INDEX($BA$2:$BA$37,MATCH(BO6,$AZ$2:$AZ$37,0)) -> 13 | BP14: =SUMIF(Calcs!$A$2:$A$37,League!BP6,Calcs!$I$2:$I$37)-INDEX($BA$2:$BA$37,MATCH(BP6,$AZ$2:$AZ$37,0)) -> 21 | ... CR14: =SUMIF(Calcs!$A$2:$A$37,League!CR6,Calcs!$I$2:$I$37)-INDEX($BA$2:$BA$37,MATCH(CR6,$AZ$2:$AZ$37,0)) -> 11
A15: 1 | B15: =Horarios!C15 -> 45918.781 | C15: =Horarios!C15 -> 45918.781 | D15: Copenhagen | E15: =INDEX(TablaEquipos[Badge],MATCH(D15,TablaEquipos[Team],0)) -> #VALUE! | G15: 2 | H15: 2 | J15: =INDEX(TablaEquipos[Badge],MATCH(K15,TablaEquipos[Team],0)) -> #VALUE! | K15: Bayer Leverkusen | N15: 14 | O15: =INDEX(TablaEquipos[],MATCH(P15,TablaEquipos[Team],0),MATCH($O$1,TablaEquipos[#Headers],0)) -> #VALUE! | P15: =IFERROR(INDEX(Calcs!A$2:A$37,MATCH($N15,Calcs!$CJ$2:$CJ$37,0)),"") -> Inter Milan | Q15: =IFERROR(INDEX(Calcs!$B$2:$AB$37,MATCH($N15,Calcs!$CJ$2:$CJ$37,0),MATCH(Q$1,Calcs!$B$1:$AB$1,0)),"") -> 12 | R15: =IFERROR(INDEX(Calcs!$B$2:$AB$37,MATCH($N15,Calcs!$CJ$2:$CJ$37,0),MATCH(R$1,Calcs!$B$1:$AB$1,0)),"") -> 7 | S15: =IFERROR(INDEX(Calcs!$B$2:$AB$37,MATCH($N15,Calcs!$CJ$2:$CJ$37,0),MATCH(S$1,Calcs!$B$1:$AB$1,0)),"") -> 4 | T15: =IFERROR(INDEX(Calcs!$B$2:$AB$37,MATCH($N15,Calcs!$CJ$2:$CJ$37,0),MATCH(T$1,Calcs!$B$1:$AB$1,0)),"") -> 0 | U15: =IFERROR(INDEX(Calcs!$B$2:$AB$37,MATCH($N15,Calcs!$CJ$2:$CJ$37,0),MATCH(U$1,Calcs!$B$1:$AB$1,0)),"") -> 3 | V15: =IFERROR(INDEX(Calcs!$B$2:$AB$37,MATCH($N15,Calcs!$CJ$2:$CJ$37,0),MATCH(V$1,Calcs!$B$1:$AB$1,0)),"") -> 13 | W15: =IFERROR(INDEX(Calcs!$B$2:$AB$37,MATCH($N15,Calcs!$CJ$2:$CJ$37,0),MATCH(W$1,Calcs!$B$1:$AB$1,0)),"") -> 7 | X15: =IFERROR(INDEX(Calcs!$B$2:$AB$37,MATCH($N15,Calcs!$CJ$2:$CJ$37,0),MATCH(X$1,Calcs!$B$1:$AB$1,0)),"") -> 6 | ... AQ15: =IFERROR(INDEX(Calcs!$B$2:$AB$37,MATCH($N15,Calcs!$CJ$2:$CJ$37,0),MATCH(AQ$1,Calcs!$B$1:$AB$1,0)),"") -> 92 | AS15: =INDEX(Calcs!A$2:A$37,MATCH($N15,Calcs!$CF$2:$CF$37,0)) -> Inter Milan | AU15: =INDEX(Calcs!$BZ$2:$BZ$37,MATCH($AS15,Calcs!$A$2:$A$37,0)) -> 14 | AV15: =COUNTIF($AU$2:$AU$37,$AU15) -> 1 | AW15: =AU15&"."&AV15 -> 14.1 | AZ15: =TablaEquipos[[#This Row],[Team]] -> Copenhagen | BF15: =IF(OR(G15="",H15=""),"Pendiente",IF(G15>H15,"Local",IF(G15<H15,"Visitante","Empate"))) -> Empate | BI15: =SUMIF(Calcs!$A$2:$A$37,League!BI7,Calcs!$I$2:$I$37)-INDEX($BA$2:$BA$37,MATCH(BI7,$AZ$2:$AZ$37,0)) -> 10 | BJ15: =SUMIF(Calcs!$A$2:$A$37,League!BJ7,Calcs!$I$2:$I$37)-INDEX($BA$2:$BA$37,MATCH(BJ7,$AZ$2:$AZ$37,0)) -> 7 | BK15: =SUMIF(Calcs!$A$2:$A$37,League!BK7,Calcs!$I$2:$I$37)-INDEX($BA$2:$BA$37,MATCH(BK7,$AZ$2:$AZ$37,0)) -> 13 | BL15: =SUMIF(Calcs!$A$2:$A$37,League!BL7,Calcs!$I$2:$I$37)-INDEX($BA$2:$BA$37,MATCH(BL7,$AZ$2:$AZ$37,0)) -> 13 | BM15: =SUMIF(Calcs!$A$2:$A$37,League!BM7,Calcs!$I$2:$I$37)-INDEX($BA$2:$BA$37,MATCH(BM7,$AZ$2:$AZ$37,0)) -> 8 | BN15: =SUMIF(Calcs!$A$2:$A$37,League!BN7,Calcs!$I$2:$I$37)-INDEX($BA$2:$BA$37,MATCH(BN7,$AZ$2:$AZ$37,0)) -> 4 | BO15: =SUMIF(Calcs!$A$2:$A$37,League!BO7,Calcs!$I$2:$I$37)-INDEX($BA$2:$BA$37,MATCH(BO7,$AZ$2:$AZ$37,0)) -> 13 | BP15: =SUMIF(Calcs!$A$2:$A$37,League!BP7,Calcs!$I$2:$I$37)-INDEX($BA$2:$BA$37,MATCH(BP7,$AZ$2:$AZ$37,0)) -> 13 | ... CR15: =SUMIF(Calcs!$A$2:$A$37,League!CR7,Calcs!$I$2:$I$37)-INDEX($BA$2:$BA$37,MATCH(CR7,$AZ$2:$AZ$37,0)) -> 8
A16: 1 | B16: =Horarios!C16 -> 45918.875 | C16: =Horarios!C16 -> 45918.875 | D16: Eintracht Frankfurt | E16: =INDEX(TablaEquipos[Badge],MATCH(D16,TablaEquipos[Team],0)) -> #VALUE! | G16: 5 | H16: 1 | J16: =INDEX(TablaEquipos[Badge],MATCH(K16,TablaEquipos[Team],0)) -> #VALUE! | K16: Galatasaray | N16: 15 | O16: =INDEX(TablaEquipos[],MATCH(P16,TablaEquipos[Team],0),MATCH($O$1,TablaEquipos[#Headers],0)) -> #VALUE! | P16: =IFERROR(INDEX(Calcs!A$2:A$37,MATCH($N16,Calcs!$CJ$2:$CJ$37,0)),"") -> Juventus | Q16: =IFERROR(INDEX(Calcs!$B$2:$AB$37,MATCH($N16,Calcs!$CJ$2:$CJ$37,0),MATCH(Q$1,Calcs!$B$1:$AB$1,0)),"") -> 12 | R16: =IFERROR(INDEX(Calcs!$B$2:$AB$37,MATCH($N16,Calcs!$CJ$2:$CJ$37,0),MATCH(R$1,Calcs!$B$1:$AB$1,0)),"") -> 7 | S16: =IFERROR(INDEX(Calcs!$B$2:$AB$37,MATCH($N16,Calcs!$CJ$2:$CJ$37,0),MATCH(S$1,Calcs!$B$1:$AB$1,0)),"") -> 3 | T16: =IFERROR(INDEX(Calcs!$B$2:$AB$37,MATCH($N16,Calcs!$CJ$2:$CJ$37,0),MATCH(T$1,Calcs!$B$1:$AB$1,0)),"") -> 3 | U16: =IFERROR(INDEX(Calcs!$B$2:$AB$37,MATCH($N16,Calcs!$CJ$2:$CJ$37,0),MATCH(U$1,Calcs!$B$1:$AB$1,0)),"") -> 1 | V16: =IFERROR(INDEX(Calcs!$B$2:$AB$37,MATCH($N16,Calcs!$CJ$2:$CJ$37,0),MATCH(V$1,Calcs!$B$1:$AB$1,0)),"") -> 14 | W16: =IFERROR(INDEX(Calcs!$B$2:$AB$37,MATCH($N16,Calcs!$CJ$2:$CJ$37,0),MATCH(W$1,Calcs!$B$1:$AB$1,0)),"") -> 10 | X16: =IFERROR(INDEX(Calcs!$B$2:$AB$37,MATCH($N16,Calcs!$CJ$2:$CJ$37,0),MATCH(X$1,Calcs!$B$1:$AB$1,0)),"") -> 4 | ... AQ16: =IFERROR(INDEX(Calcs!$B$2:$AB$37,MATCH($N16,Calcs!$CJ$2:$CJ$37,0),MATCH(AQ$1,Calcs!$B$1:$AB$1,0)),"") -> 87 | AS16: =INDEX(Calcs!A$2:A$37,MATCH($N16,Calcs!$CF$2:$CF$37,0)) -> Juventus | AU16: =INDEX(Calcs!$BZ$2:$BZ$37,MATCH($AS16,Calcs!$A$2:$A$37,0)) -> 15 | AV16: =COUNTIF($AU$2:$AU$37,$AU16) -> 1 | AW16: =AU16&"."&AV16 -> 15.1 | AZ16: =TablaEquipos[[#This Row],[Team]] -> Eintracht Frankfurt | BF16: =IF(OR(G16="",H16=""),"Pendiente",IF(G16>H16,"Local",IF(G16<H16,"Visitante","Empate"))) -> Local | BI16: =SUMIF(Calcs!$A$2:$A$37,League!BI8,Calcs!$I$2:$I$37)-INDEX($BA$2:$BA$37,MATCH(BI8,$AZ$2:$AZ$37,0)) -> 1 | BJ16: =SUMIF(Calcs!$A$2:$A$37,League!BJ8,Calcs!$I$2:$I$37)-INDEX($BA$2:$BA$37,MATCH(BJ8,$AZ$2:$AZ$37,0)) -> 12 | BK16: =SUMIF(Calcs!$A$2:$A$37,League!BK8,Calcs!$I$2:$I$37)-INDEX($BA$2:$BA$37,MATCH(BK8,$AZ$2:$AZ$37,0)) -> 8 | BL16: =SUMIF(Calcs!$A$2:$A$37,League!BL8,Calcs!$I$2:$I$37)-INDEX($BA$2:$BA$37,MATCH(BL8,$AZ$2:$AZ$37,0)) -> 13 | BM16: =SUMIF(Calcs!$A$2:$A$37,League!BM8,Calcs!$I$2:$I$37)-INDEX($BA$2:$BA$37,MATCH(BM8,$AZ$2:$AZ$37,0)) -> 10 | BN16: =SUMIF(Calcs!$A$2:$A$37,League!BN8,Calcs!$I$2:$I$37)-INDEX($BA$2:$BA$37,MATCH(BN8,$AZ$2:$AZ$37,0)) -> 3 | BO16: =SUMIF(Calcs!$A$2:$A$37,League!BO8,Calcs!$I$2:$I$37)-INDEX($BA$2:$BA$37,MATCH(BO8,$AZ$2:$AZ$37,0)) -> 8 | BP16: =SUMIF(Calcs!$A$2:$A$37,League!BP8,Calcs!$I$2:$I$37)-INDEX($BA$2:$BA$37,MATCH(BP8,$AZ$2:$AZ$37,0)) -> 6 | ... CR16: =SUMIF(Calcs!$A$2:$A$37,League!CR8,Calcs!$I$2:$I$37)-INDEX($BA$2:$BA$37,MATCH(CR8,$AZ$2:$AZ$37,0)) -> 6
A17: 1 | B17: =Horarios!C17 -> 45918.875 | C17: =Horarios!C17 -> 45918.875 | D17: Manchester City | E17: =INDEX(TablaEquipos[Badge],MATCH(D17,TablaEquipos[Team],0)) -> #VALUE! | G17: 2 | H17: 0 | J17: =INDEX(TablaEquipos[Badge],MATCH(K17,TablaEquipos[Team],0)) -> #VALUE! | K17: Napoli | N17: 16 | O17: =INDEX(TablaEquipos[],MATCH(P17,TablaEquipos[Team],0),MATCH($O$1,TablaEquipos[#Headers],0)) -> #VALUE! | P17: =IFERROR(INDEX(Calcs!A$2:A$37,MATCH($N17,Calcs!$CJ$2:$CJ$37,0)),"") -> Borussia Dortmund | Q17: =IFERROR(INDEX(Calcs!$B$2:$AB$37,MATCH($N17,Calcs!$CJ$2:$CJ$37,0),MATCH(Q$1,Calcs!$B$1:$AB$1,0)),"") -> 11 | R17: =IFERROR(INDEX(Calcs!$B$2:$AB$37,MATCH($N17,Calcs!$CJ$2:$CJ$37,0),MATCH(R$1,Calcs!$B$1:$AB$1,0)),"") -> 7 | S17: =IFERROR(INDEX(Calcs!$B$2:$AB$37,MATCH($N17,Calcs!$CJ$2:$CJ$37,0),MATCH(S$1,Calcs!$B$1:$AB$1,0)),"") -> 3 | T17: =IFERROR(INDEX(Calcs!$B$2:$AB$37,MATCH($N17,Calcs!$CJ$2:$CJ$37,0),MATCH(T$1,Calcs!$B$1:$AB$1,0)),"") -> 2 | U17: =IFERROR(INDEX(Calcs!$B$2:$AB$37,MATCH($N17,Calcs!$CJ$2:$CJ$37,0),MATCH(U$1,Calcs!$B$1:$AB$1,0)),"") -> 2 | V17: =IFERROR(INDEX(Calcs!$B$2:$AB$37,MATCH($N17,Calcs!$CJ$2:$CJ$37,0),MATCH(V$1,Calcs!$B$1:$AB$1,0)),"") -> 19 | W17: =IFERROR(INDEX(Calcs!$B$2:$AB$37,MATCH($N17,Calcs!$CJ$2:$CJ$37,0),MATCH(W$1,Calcs!$B$1:$AB$1,0)),"") -> 15 | X17: =IFERROR(INDEX(Calcs!$B$2:$AB$37,MATCH($N17,Calcs!$CJ$2:$CJ$37,0),MATCH(X$1,Calcs!$B$1:$AB$1,0)),"") -> 4 | ... AQ17: =IFERROR(INDEX(Calcs!$B$2:$AB$37,MATCH($N17,Calcs!$CJ$2:$CJ$37,0),MATCH(AQ$1,Calcs!$B$1:$AB$1,0)),"") -> 90 | AS17: =INDEX(Calcs!A$2:A$37,MATCH($N17,Calcs!$CF$2:$CF$37,0)) -> Borussia Dortmund | AU17: =INDEX(Calcs!$BZ$2:$BZ$37,MATCH($AS17,Calcs!$A$2:$A$37,0)) -> 16 | AV17: =COUNTIF($AU$2:$AU$37,$AU17) -> 1 | AW17: =AU17&"."&AV17 -> 16.1 | AZ17: =TablaEquipos[[#This Row],[Team]] -> Galatasaray | BF17: =IF(OR(G17="",H17=""),"Pendiente",IF(G17>H17,"Local",IF(G17<H17,"Visitante","Empate"))) -> Local | BI17: =SUMIF(Calcs!$A$2:$A$37,League!BI9,Calcs!$I$2:$I$37)-INDEX($BA$2:$BA$37,MATCH(BI9,$AZ$2:$AZ$37,0)) -> 8 | BJ17: =SUMIF(Calcs!$A$2:$A$37,League!BJ9,Calcs!$I$2:$I$37)-INDEX($BA$2:$BA$37,MATCH(BJ9,$AZ$2:$AZ$37,0)) -> 1 | BK17: =SUMIF(Calcs!$A$2:$A$37,League!BK9,Calcs!$I$2:$I$37)-INDEX($BA$2:$BA$37,MATCH(BK9,$AZ$2:$AZ$37,0)) -> 6 | BL17: =SUMIF(Calcs!$A$2:$A$37,League!BL9,Calcs!$I$2:$I$37)-INDEX($BA$2:$BA$37,MATCH(BL9,$AZ$2:$AZ$37,0)) -> 13 | BM17: =SUMIF(Calcs!$A$2:$A$37,League!BM9,Calcs!$I$2:$I$37)-INDEX($BA$2:$BA$37,MATCH(BM9,$AZ$2:$AZ$37,0)) -> 6 | BN17: =SUMIF(Calcs!$A$2:$A$37,League!BN9,Calcs!$I$2:$I$37)-INDEX($BA$2:$BA$37,MATCH(BN9,$AZ$2:$AZ$37,0)) -> 8 | BO17: =SUMIF(Calcs!$A$2:$A$37,League!BO9,Calcs!$I$2:$I$37)-INDEX($BA$2:$BA$37,MATCH(BO9,$AZ$2:$AZ$37,0)) -> 1 | BP17: =SUMIF(Calcs!$A$2:$A$37,League!BP9,Calcs!$I$2:$I$37)-INDEX($BA$2:$BA$37,MATCH(BP9,$AZ$2:$AZ$37,0)) -> 8 | ... CR17: =SUMIF(Calcs!$A$2:$A$37,League!CR9,Calcs!$I$2:$I$37)-INDEX($BA$2:$BA$37,MATCH(CR9,$AZ$2:$AZ$37,0)) -> 9
A18: 1 | B18: =Horarios!C18 -> 45918.875 | C18: =Horarios!C18 -> 45918.875 | D18: Newcastle | E18: =INDEX(TablaEquipos[Badge],MATCH(D18,TablaEquipos[Team],0)) -> #VALUE! | G18: 1 | H18: 2 | J18: =INDEX(TablaEquipos[Badge],MATCH(K18,TablaEquipos[Team],0)) -> #VALUE! | K18: Barcelona | N18: 17 | O18: =INDEX(TablaEquipos[],MATCH(P18,TablaEquipos[Team],0),MATCH($O$1,TablaEquipos[#Headers],0)) -> #VALUE! | P18: =IFERROR(INDEX(Calcs!A$2:A$37,MATCH($N18,Calcs!$CJ$2:$CJ$37,0)),"") -> Galatasaray | Q18: =IFERROR(INDEX(Calcs!$B$2:$AB$37,MATCH($N18,Calcs!$CJ$2:$CJ$37,0),MATCH(Q$1,Calcs!$B$1:$AB$1,0)),"") -> 10 | R18: =IFERROR(INDEX(Calcs!$B$2:$AB$37,MATCH($N18,Calcs!$CJ$2:$CJ$37,0),MATCH(R$1,Calcs!$B$1:$AB$1,0)),"") -> 7 | S18: =IFERROR(INDEX(Calcs!$B$2:$AB$37,MATCH($N18,Calcs!$CJ$2:$CJ$37,0),MATCH(S$1,Calcs!$B$1:$AB$1,0)),"") -> 3 | T18: =IFERROR(INDEX(Calcs!$B$2:$AB$37,MATCH($N18,Calcs!$CJ$2:$CJ$37,0),MATCH(T$1,Calcs!$B$1:$AB$1,0)),"") -> 1 | U18: =IFERROR(INDEX(Calcs!$B$2:$AB$37,MATCH($N18,Calcs!$CJ$2:$CJ$37,0),MATCH(U$1,Calcs!$B$1:$AB$1,0)),"") -> 3 | V18: =IFERROR(INDEX(Calcs!$B$2:$AB$37,MATCH($N18,Calcs!$CJ$2:$CJ$37,0),MATCH(V$1,Calcs!$B$1:$AB$1,0)),"") -> 9 | W18: =IFERROR(INDEX(Calcs!$B$2:$AB$37,MATCH($N18,Calcs!$CJ$2:$CJ$37,0),MATCH(W$1,Calcs!$B$1:$AB$1,0)),"") -> 9 | X18: =IFERROR(INDEX(Calcs!$B$2:$AB$37,MATCH($N18,Calcs!$CJ$2:$CJ$37,0),MATCH(X$1,Calcs!$B$1:$AB$1,0)),"") -> 0 | ... AQ18: =IFERROR(INDEX(Calcs!$B$2:$AB$37,MATCH($N18,Calcs!$CJ$2:$CJ$37,0),MATCH(AQ$1,Calcs!$B$1:$AB$1,0)),"") -> 87 | AS18: =INDEX(Calcs!A$2:A$37,MATCH($N18,Calcs!$CF$2:$CF$37,0)) -> Galatasaray | AU18: =INDEX(Calcs!$BZ$2:$BZ$37,MATCH($AS18,Calcs!$A$2:$A$37,0)) -> 17 | AV18: =COUNTIF($AU$2:$AU$37,$AU18) -> 1 | AW18: =AU18&"."&AV18 -> 17.1 | AZ18: =TablaEquipos[[#This Row],[Team]] -> Inter Milan | BF18: =IF(OR(G18="",H18=""),"Pendiente",IF(G18>H18,"Local",IF(G18<H18,"Visitante","Empate"))) -> Visitante | BH18: Puntos Oponentes | BI18: =SUM(BI10:BI17) -> 69 | BJ18: =SUM(BJ10:BJ17) -> 70 | BK18: =SUM(BK10:BK17) -> 63 | BL18: =SUM(BL10:BL17) -> 97 | BM18: =SUM(BM10:BM17) -> 82 | BN18: =SUM(BN10:BN17) -> 69 | BO18: =SUM(BO10:BO17) -> 70 | BP18: =SUM(BP10:BP17) -> 87 | ... CR18: =SUM(CR10:CR17) -> 79
A19: 1 | B19: =Horarios!C19 -> 45918.875 | C19: =Horarios!C19 -> 45918.875 | D19: Sporting Portugal | E19: =INDEX(TablaEquipos[Badge],MATCH(D19,TablaEquipos[Team],0)) -> #VALUE! | G19: 4 | H19: 1 | J19: =INDEX(TablaEquipos[Badge],MATCH(K19,TablaEquipos[Team],0)) -> #VALUE! | K19: Kairat Almaty | N19: 18 | O19: =INDEX(TablaEquipos[],MATCH(P19,TablaEquipos[Team],0),MATCH($O$1,TablaEquipos[#Headers],0)) -> #VALUE! | P19: =IFERROR(INDEX(Calcs!A$2:A$37,MATCH($N19,Calcs!$CJ$2:$CJ$37,0)),"") -> Qarabağ | Q19: =IFERROR(INDEX(Calcs!$B$2:$AB$37,MATCH($N19,Calcs!$CJ$2:$CJ$37,0),MATCH(Q$1,Calcs!$B$1:$AB$1,0)),"") -> 10 | R19: =IFERROR(INDEX(Calcs!$B$2:$AB$37,MATCH($N19,Calcs!$CJ$2:$CJ$37,0),MATCH(R$1,Calcs!$B$1:$AB$1,0)),"") -> 7 | S19: =IFERROR(INDEX(Calcs!$B$2:$AB$37,MATCH($N19,Calcs!$CJ$2:$CJ$37,0),MATCH(S$1,Calcs!$B$1:$AB$1,0)),"") -> 3 | T19: =IFERROR(INDEX(Calcs!$B$2:$AB$37,MATCH($N19,Calcs!$CJ$2:$CJ$37,0),MATCH(T$1,Calcs!$B$1:$AB$1,0)),"") -> 1 | U19: =IFERROR(INDEX(Calcs!$B$2:$AB$37,MATCH($N19,Calcs!$CJ$2:$CJ$37,0),MATCH(U$1,Calcs!$B$1:$AB$1,0)),"") -> 3 | V19: =IFERROR(INDEX(Calcs!$B$2:$AB$37,MATCH($N19,Calcs!$CJ$2:$CJ$37,0),MATCH(V$1,Calcs!$B$1:$AB$1,0)),"") -> 13 | W19: =IFERROR(INDEX(Calcs!$B$2:$AB$37,MATCH($N19,Calcs!$CJ$2:$CJ$37,0),MATCH(W$1,Calcs!$B$1:$AB$1,0)),"") -> 15 | X19: =IFERROR(INDEX(Calcs!$B$2:$AB$37,MATCH($N19,Calcs!$CJ$2:$CJ$37,0),MATCH(X$1,Calcs!$B$1:$AB$1,0)),"") -> -2 | ... AQ19: =IFERROR(INDEX(Calcs!$B$2:$AB$37,MATCH($N19,Calcs!$CJ$2:$CJ$37,0),MATCH(AQ$1,Calcs!$B$1:$AB$1,0)),"") -> 76 | AS19: =INDEX(Calcs!A$2:A$37,MATCH($N19,Calcs!$CF$2:$CF$37,0)) -> Qarabağ | AU19: =INDEX(Calcs!$BZ$2:$BZ$37,MATCH($AS19,Calcs!$A$2:$A$37,0)) -> 18 | AV19: =COUNTIF($AU$2:$AU$37,$AU19) -> 1 | AW19: =AU19&"."&AV19 -> 18.1 | AZ19: =TablaEquipos[[#This Row],[Team]] -> Juventus | BF19: =IF(OR(G19="",H19=""),"Pendiente",IF(G19>H19,"Local",IF(G19<H19,"Visitante","Empate"))) -> Local | BH19: DG | BI19: =SUMIF(Calcs!$A$2:$A$37,League!BI2,Calcs!$H$2:$H$37) -> 6 | BJ19: =SUMIF(Calcs!$A$2:$A$37,League!BJ2,Calcs!$H$2:$H$37) -> -4 | BK19: =SUMIF(Calcs!$A$2:$A$37,League!BK2,Calcs!$H$2:$H$37) -> 10 | BL19: =SUMIF(Calcs!$A$2:$A$37,League!BL2,Calcs!$H$2:$H$37) -> 18 | BM19: =SUMIF(Calcs!$A$2:$A$37,League!BM2,Calcs!$H$2:$H$37) -> 6 | BN19: =SUMIF(Calcs!$A$2:$A$37,League!BN2,Calcs!$H$2:$H$37) -> 10 | BO19: =SUMIF(Calcs!$A$2:$A$37,League!BO2,Calcs!$H$2:$H$37) -> -6 | BP19: =SUMIF(Calcs!$A$2:$A$37,League!BP2,Calcs!$H$2:$H$37) -> 6 | ... CR19: =SUMIF(Calcs!$A$2:$A$37,League!CR2,Calcs!$H$2:$H$37) -> 8
